Workbook

Sheet AUTO 2026
B1: Assureur | C1: Immatriculation | D1: Modèle | E1: Propriétaire | F1: Leasing | H1: Assurés | I1: Conducteur | J1: Courtier | K1: N° Contrat | L1: Souscripteur | M1: Périodicité | N1: Renouvellement | O1: Préavis | P1: Date de souscription | Q1: Primes contrats TTC | R1: Mémo Carte Verte | S1: Sinistralité | AA1: Coef B/M | AB1: Primes TTC | AE1: Résiliation | AH1: Nb de sinistre | AI1: % | AJ1: Coût | AK1: %
F2: Début | G2: Fin | S2: Date | T2: Type | U2: R | V2: Coût | W2: Franchises | X2: Autres* | Y2: Ratio % | Z2: Nombre | AB2: Date | AC2: Primes hors BM | AD2: Primes réglées avec BM | AG2: COLL
A3: 1 | B3: A1 | C3: I97 | D3: PEUGEOT 3008 7CV PURETECH 130 S | E3: P1 | F3: 45212 | G3: 46307 | H3: R1 | I3: - | J3: NEANT | K3: 97 | L3: S1 | M3: Annuelle | N3: 45658 | O3: 2 MOIS | P3: 45435 | Q3: - | R3: - | AA3: 0.5 | AB3: 45994 | AC3: =AD3/AA3 -> 2000.46 | AD3: 1000.23 | AG3: ACC
A4: 1 | B4: A1 | C4: I96 | D4: PEUGEOT 2008 5 CV PURETECH 100 ALL | E4: P1 | H4: R1 | I4: C96 | J4: NEANT | K4: 96 | L4: S1 | M4: Annuelle | N4: 45658 | O4: 2 MOIS | P4: 45824 | Q4: - | R4: - | AA4: 0.5 | AB4: 45994 | AC4: =AD4/AA4 -> 1505.3 | AD4: 752.65 | AG4: BDG | AH4: 1 | AI4: =AH4/AH5*100 -> 100 | AK4: =AJ4/AJ5*100 -> #DIV/0!
A5: 1 | B5: A1 | C5: I95 | D5: PEUGEOT e208 4CV ELECTRIQUE ACTIVE PA | E5: P1 | F5: 45698 | G5: 46792 | H5: R1 | I5: - | J5: NEANT | K5: 95 | L5: S1 | M5: Annuelle | N5: 45658 | O5: 2 MOIS | P5: 45698 | Q5: - | R5: - | AA5: 0.5 | AB5: 45994 | AC5: =AD5/AA5 -> 1874.94 | AD5: 937.47 | AH5: =SUM(AH2:AH4) -> 1 | AI5: =SUM(AI2:AI4) -> 100 | AJ5: =SUM(AJ2:AJ4) -> 0 | AK5: =SUM(AK2:AK4) -> #DIV/0!
A6: 1 | B6: A1 | C6: I94 | D6: PEUGEOT e208 4CV ELECTRIQUE ACTIVE PA | E6: P1 | F6: 45709 | G6: 46803 | H6: R1 | I6: - | J6: NEANT | K6: 94 | L6: S1 | M6: Annuelle | N6: 45658 | O6: 2 MOIS | P6: 45709 | Q6: - | R6: - | AA6: 0.5 | AB6: 45994 | AC6: =AD6/AA6 -> 1874.94 | AD6: 937.47
A7: 1 | B7: A1 | C7: I93 | D7: PEUGEOT e208 4CV ELECTRIQUE ACTIVE PA | E7: P1 | F7: 45709 | G7: 46803 | H7: R1 | I7: - | J7: NEANT | K7: 93 | L7: S1 | M7: Annuelle | N7: 45658 | O7: 2 MOIS | P7: 45709 | Q7: - | R7: - | AA7: 0.5 | AB7: 45994 | AC7: =AD7/AA7 -> 1874.94 | AD7: 937.47
A8: 1 | B8: A1 | C8: I92 | D8: PEUGEOT e208 4CV ELECTRIQUE ACTIVE PA | E8: P1 | F8: 45698 | G8: 46792 | H8: R1 | I8: - | J8: NEANT | K8: 92 | L8: S1 | M8: Annuelle | N8: 45658 | O8: 2 MOIS | P8: 45698 | Q8: - | R8: - | AA8: 0.5 | AB8: 45994 | AC8: =AD8/AA8 -> 1874.94 | AD8: 937.47
A9: 1 | B9: A1 | C9: I91 | D9: PEUGEOT 208 5CV PURETECH 100 ACT | E9: P1 | F9: 45698 | G9: 46792 | H9: R1 | I9: - | J9: NEANT | K9: 91 | L9: S1 | M9: Annuelle | N9: 45658 | O9: 2 MOIS | P9: 45698 | Q9: - | R9: - | AA9: 0.5 | AB9: 45994 | AC9: =AD9/AA9 -> 1977.82 | AD9: 988.91
A10: 1 | B10: A1 | C10: I90 | D10: PEUGEOT 208 5CV PURETECH 100 ACT | E10: P1 | F10: 45698 | G10: 46792 | H10: R1 | I10: - | J10: NEANT | K10: 90 | L10: S1 | M10: Annuelle | N10: 45658 | O10: 2 MOIS | P10: 45698 | Q10: - | R10: - | AA10: 0.5 | AB10: 45994 | AC10: =AD10/AA10 -> 1977.82 | AD10: 988.91
A11: 1 | B11: A1 | C11: I89 | D11: PEUGEOT 308 7CV HYBRID 136 ACTIV | E11: P1 | F11: 45698 | G11: 46792 | H11: R1 | I11: C89 | J11: NEANT | K11: 89 | L11: S1 | M11: Annuelle | N11: 45658 | O11: 2 MOIS | P11: 45671 | Q11: - | R11: - | AA11: 0.5 | AB11: 45994 | AC11: =AD11/AA11 -> 2530.38 | AD11: 1265.19
A12: 1 | B12: A1 | C12: I88 | D12: PEUGEOT e208 4CV ELECTRIQUE ACTIVE PA | E12: P1 | F12: 45698 | G12: 46792 | H12: R1 | I12: - | J12: NEANT | K12: 88 | L12: S1 | M12: Annuelle | N12: 45658 | O12: 2 MOIS | P12: 45698 | Q12: - | R12: - | AA12: 0.5 | AB12: 45994 | AC12: =AD12/AA12 -> 1927.78 | AD12: 963.89
A13: 1 | B13: A1 | C13: I87 | D13: PEUGEOT 308 SW 7CV HYB.136 GT | E13: P1 | F13: 45644 | G13: 46738 | H13: R1 | I13: C87 | J13: NEANT | K13: 87 | L13: S1 | M13: Annuelle | N13: 45658 | O13: 2 MOIS | P13: 45644 | Q13: - | R13: - | AA13: 0.5 | AB13: 45994 | AC13: =AD13/AA13 -> 2383.36 | AD13: 1191.68
A14: 1 | B14: A1 | C14: I86 | D14: PEUGEOT 5008 7CV PURETECH 130A | E14: P2 | F14: 44908 | G14: 46003 | H14: R1 | I14: C86 | J14: NEANT | K14: 86 | L14: S1 | M14: Annuelle | N14: 45658 | O14: 2 MOIS | P14: 45324 | Q14: - | R14: - | AA14: 0.58 | AB14: 45994 | AC14: =AD14/AA14 -> 2375.6379 | AD14: 1377.87
A15: 1 | B15: A1 | C15: I85 | D15: PEUGEOT 308 SW 6CV E-THP 110 ACT | E15: P2 | F15: 44835 | G15: 45929 | H15: R1 | I15: C85 | J15: NEANT | K15: 85 | L15: S1 | M15: Annuelle | N15: 45658 | O15: 2 MOIS | P15: 45435 | Q15: - | R15: - | S15: 46029 | T15: BDG | U15: 0 | W15: 0 | Y15: =V15/AD15*100 -> 0 | Z15: 1 | AA15: 0.5 | AB15: 45994 | AC15: =AD15/AA15 -> 2144.58 | AD15: 1072.29
A16: 1 | B16: A1 | C16: I83 | D16: PEUGEOT 208 5CV PURETECH 100 ALL | E16: P2 | F16: 45177 | G16: 46272 | H16: R1 | I16: C83 | J16: NEANT | K16: 83 | L16: S1 | M16: Annuelle | N16: 45658 | O16: 2 MOIS | P16: 45435 | Q16: - | R16: - | AA16: 0.5 | AB16: 45994 | AC16: =AD16/AA16 -> 2331.16 | AD16: 1165.58
A17: 1 | B17: A1 | C17: I82 | D17: PEUGEOT 208 5CV PURETECH 100 ALL | E17: P2 | F17: 45089 | G17: 46184 | H17: R1 | I17: - | J17: NEANT | K17: 82 | L17: S1 | M17: Annuelle | N17: 45658 | O17: 2 MOIS | P17: 45435 | Q17: - | R17: - | AA17: 0.5 | AB17: 45994 | AC17: =AD17/AA17 -> 2432.28 | AD17: 1216.14
A18: 1 | B18: A1 | C18: I81 | D18: PEUGEOT 208 5CV PURTECH 100 ALL | E18: P2 | F18: 45089 | G18: 46184 | H18: R1 | I18: C81 | J18: NEANT | K18: 81 | L18: S1 | M18: Annuelle | N18: 45658 | O18: 2 MOIS | P18: 45435 | Q18: - | R18: - | AA18: 0.5 | AB18: 45994 | AC18: =AD18/AA18 -> 2331.9 | AD18: 1165.95
A19: 1 | B19: A1 | C19: I80 | D19: BMW X3 10CV 20i XD 184 | E19: P3 | F19: 45076 | G19: 46171 | H19: R1 | I19: C80 | J19: NEANT | K19: 80 | L19: S1 | M19: Annuelle | N19: 45658 | O19: 2 MOIS | P19: 45076 | Q19: - | R19: - | AA19: 0.5 | AB19: 45994 | AC19: =AD19/AA19 -> 4770.76 | AD19: 2385.38
A20: 1 | B20: A1 | C20: I79 | D20: PEUGEOT 208 5CV PURETECH 100 ALL | E20: P2 | F20: 45027 | G20: 46122 | H20: R1 | I20: C79 | J20: NEANT | K20: 79 | L20: S1 | M20: Annuelle | N20: 45658 | O20: 2 MOIS | P20: 46123 | Q20: - | R20: - | AA20: 0.5 | AB20: 45994 | AC20: =AD20/AA20 -> 2510.92 | AD20: 1255.46
A21: 1 | B21: A1 | C21: I78 | D21: PEUGEOT 308 SW 6CV E-THP 110 ACT | E21: P3 | F21: 44978 | G21: 46073 | H21: R1 | I21: C78 | J21: NEANT | K21: 78 | L21: S1 | M21: Annuelle | N21: 45658 | O21: 2 MOIS | P21: 44978 | Q21: - | R21: - | AA21: 0.5 | AB21: 45994 | AC21: =AD21/AA21 -> 2214.76 | AD21: 1107.38
A22: 0 | B22: A1 | C22: I77 | D22: PEUGEOT 208 5CV PURETECH 100 ACT | E22: P2 | F22: 44915 | G22: 46010 | H22: R1 | I22: - | J22: NEANT | K22: 77 | L22: S1 | M22: Annuelle | N22: 45658 | O22: 2 MOIS | P22: 44908 | Q22: - | R22: - | AA22: 0.5 | AB22: 45994 | AC22: =AD22/AA22 -> 2672.02 | AD22: 1336.01 | AE22: 46010
AA23: 0.5 | AB23: 46015 | AD23: -1380.94
A24: 1 | B24: A1 | C24: I75 | D24: PEUGEOT 208 5CV PURETECH 100 ALL | E24: P2 | F24: 44878 | G24: 45973 | H24: R1 | I24: - | J24: NEANT | K24: 75 | L24: S1 | M24: Annuelle | N24: 45658 | O24: 2 MOIS | P24: 44878 | Q24: - | R24: - | AA24: 0.5 | AB24: 45994 | AC24: =AD24/AA24 -> 2170.26 | AD24: 1085.13
A25: 1 | B25: A1 | C25: I74 | D25: PEUGEOT 208 5CV PURETECH 100 ALL | E25: P2 | F25: 44885 | G25: 45980 | H25: R1 | I25: - | J25: NEANT | K25: 74 | L25: S1 | M25: Annuelle | N25: 45658 | O25: 2 MOIS | P25: 44885 | Q25: - | R25: - | AA25: 0.5 | AB25: 45994 | AC25: =AD25/AA25 -> 2190.82 | AD25: 1095.41
A26: 1 | B26: A1 | C26: I72 | D26: PEUGEOT 208 5CV PURETECH 100 ACT | E26: P2 | F26: 44827 | G26: 45922 | H26: R1 | I26: - | J26: NEANT | K26: 72 | L26: S1 | M26: Annuelle | N26: 45658 | O26: 2 MOIS | P26: 44827 | Q26: - | R26: - | AA26: 0.5 | AB26: 45994 | AC26: =AD26/AA26 -> 2177.46 | AD26: 1088.73
A27: 1 | B27: A1 | C27: I71 | D27: PEUGEOT 208 5CV PURETECH 100 ACT | E27: P2 | F27: 44855 | G27: 45950 | H27: R1 | I27: - | J27: NEANT | K27: 71 | L27: S1 | M27: Annuelle | N27: 45658 | O27: 2 MOIS | P27: 44855 | Q27: - | R27: - | AA27: 0.5 | AB27: 45994 | AC27: =AD27/AA27 -> 2419.74 | AD27: 1209.87
A28: 1 | B28: A1 | C28: I70 | D28: PEUGEOT 208 5CV PURETECH 100 ACT | E28: P2 | F28: 44841 | G28: 45936 | H28: R1 | I28: C70 | J28: NEANT | K28: 70 | L28: S1 | M28: Annuelle | N28: 45658 | O28: 2 MOIS | P28: 44841 | Q28: - | R28: - | AA28: 0.5 | AB28: 45994 | AC28: =AD28/AA28 -> 2318.52 | AD28: 1159.26
A29: 0 | B29: A1 | C29: I69 | D29: PEUGEOT 208 5CV PURETECH 100 ACT | E29: P2 | F29: 44840 | G29: 45935 | H29: R1 | I29: - | J29: NEANT | K29: 69 | L29: S1 | M29: Annuelle | N29: 45658 | O29: 2 MOIS | P29: 44839 | Q29: - | R29: - | AA29: 0.5 | AB29: 45994 | AC29: =AD29/AA29 -> 2183.9 | AD29: 1091.95 | AE29: 45970
AA30: 0.5 | AB30: 46027 | AD30: -1242.94
A31: 0 | B31: A1 | C31: I68 | D31: PEUGEOT 208 5CV PURETECH 100 ACT | E31: P2 | F31: 44840 | G31: 45935 | H31: R1 | I31: - | J31: NEANT | K31: 68 | L31: S1 | M31: Annuelle | N31: 45658 | O31: 2 MOIS | P31: 44839 | Q31: - | R31: - | AA31: 0.5 | AB31: 45994 | AC31: =AD31/AA31 -> 2183.28 | AD31: 1091.64 | AE31: 45970
AA32: 0.5 | AB32: 46027 | AD32: -1242.59
A33: 1 | B33: A1 | C33: I65 | D33: PEUGEOT 308 6 CV PURETECH ACT | E33: P2 | F33: 44754 | G33: 45849 | H33: R1 | I33: C65 | J33: NEANT | K33: 65 | L33: S1 | M33: Annuelle | N33: 45658 | O33: 2 MOIS | P33: 44754 | Q33: - | R33: - | AA33: 0.5 | AB33: 45994 | AC33: =AD33/AA33 -> 2407.44 | AD33: 1203.72
A34: 1 | B34: A1 | C34: I63 | D34: PEUGEOT 308 SW PURETECH 110 | E34: P2 | F34: 44760 | G34: 45855 | H34: R1 | I34: C63 | J34: NEANT | K34: 63 | L34: S1 | M34: Annuelle | N34: 45658 | O34: 2 MOIS | P34: 44760 | Q34: - | R34: - | AA34: 0.62 | AB34: 45994 | AC34: =AD34/AA34 -> 2946.3871 | AD34: 1826.76
A35: =SUM(A3:A34) -> 26
Q36: =SUM(Q3:Q34) -> 0 | S36: SOUS TOTAL | V36: =SUM(V3:V34) -> 0 | W36: =SUM(W3:W34) -> 0 | X36: =SUM(X3:X34) -> 0 | Z36: =SUM(Z3:Z34) -> 1 | AC36: =SUM(AC3:AC34) -> 66584.505 | AD36: =SUM(AD3:AD34) -> 29969.4 | AF36: 29 969,40 € au total pour 2026
B37: VOITURE DE FONCTION | D37: =SUM(A4+A11+A13+A14+A15+A16+A18+A19+A20+A21+A28+A33+A34) -> 13
B38: VOITURE DE SERVICE | D38: =SUM(A3+A5+A6+A7+A8+A9+A10+A12+A17+A22+A24+A25+A26+A27+A29+A31) -> 13
D39: =SUM(D37:D38) -> 26 | S39: COUT SINISTRES | V39: =SUM(V36:X36) -> 0 | X39: COUT ASSUREUR | Y39: =V36 -> 0 | AB39: COUT ASSURE | AC39: =SUM(W36:X36)+AD36 -> 29969.4
B41: *Coût des réparations non déclarées, prévention, formation, TVA, frais de gestion... | S41: IMPACT TARIFAIRE | V41: PRIMES | W41: SINISTRES | X41: DELTA | Y41: RATIO S/P | AC41: Nombre | AD41: % | AE41: Coût | AF41: %
...

Sheet AUTO 2025
B1: Assureur | C1: Immatriculation | D1: Modèle | E1: Propriétaire | F1: Leasing | H1: Assurés | I1: Conducteur | J1: Courtier | K1: N° Contrat | L1: Souscripteur | M1: Périodicité | N1: Renouvellement | O1: Préavis | P1: Date de souscription | Q1: Primes contrats TTC | R1: Mémo Carte Verte | S1: Sinistralité | AA1: Coef BM | AB1: Primes TTC | AE1: Résiliation
F2: Début | G2: Fin | S2: Date | T2: Type | U2: R | V2: Coût | W2: Franchises | X2: Autres* | Y2: Ratio % | Z2: Nombre | AB2: Date | AC2: Primes hors BM | AD2: Primes réglées avec BM
A3: 1 | B3: A1 | C3: I96 | D3: PEUGEOT 2008 5 CV PURETECH 100 ALL | E3: P1 | H3: R1 | I3: C96 | J3: NEANT | K3: 96 | L3: S1 | M3: Annuelle | N3: 45658 | O3: 2 MOIS | P3: 45824 | Q3: =715.2/AA3 -> 1430.4 | R3: 45824 | S3: 45945 | T3: BDG | V3: 194.16 | W3: 0 | Y3: =V3/AD3*100 -> 49.432252 | Z3: 1 | AA3: 0.5 | AB3: 45856 | AC3: =Q3 -> 1430.4 | AD3: 392.78
A4: 1 | B4: A1 | C4: I95 | D4: PEUGEOT e208 4CV ELECTRIQUE ACTIVE PA | E4: P1 | F4: 45698 | G4: 46792 | H4: R1 | I4: - | J4: NEANT | K4: 95 | L4: S1 | M4: Annuelle | N4: 45658 | O4: 2 MOIS | P4: 45709 | Q4: =896.62/AA4 -> 1793.24 | R4: 45708 | AA4: 0.5 | AB4: 45708 | AC4: =Q4 -> 1793.24 | AD4: 772.07
A5: 1 | B5: A1 | C5: I94 | D5: PEUGEOT e208 4CV ELECTRIQUE ACTIVE PA | E5: P1 | F5: 45709 | G5: 46803 | H5: R1 | I5: - | J5: NEANT | K5: 94 | L5: S1 | M5: Annuelle | N5: 45658 | O5: 2 MOIS | P5: 45709 | Q5: =896.62/AA5 -> 1793.24 | R5: 45708 | AA5: 0.5 | AB5: 45708 | AC5: =Q5 -> 1793.24 | AD5: 772.07
A6: 1 | B6: A1 | C6: I93 | D6: PEUGEOT e208 4CV ELECTRIQUE ACTIVE PA | E6: P1 | F6: 45709 | G6: 46803 | H6: R1 | I6: - | J6: NEANT | K6: 93 | L6: S1 | M6: Annuelle | N6: 45658 | O6: 2 MOIS | P6: 45709 | Q6: =896.62/AA6 -> 1793.24 | R6: 45708 | S6: 45747 | T6: BDG | U6: 0 | V6: 235 | W6: 0 | Y6: =V6/AD6*100 -> 30.437655 | Z6: 1 | AA6: 0.5 | AB6: 45708 | AC6: =Q6 -> 1793.24 | AD6: 772.07
A7: 1 | B7: A1 | C7: I92 | D7: PEUGEOT e208 4CV ELECTRIQUE ACTIVE PA | E7: P1 | F7: 45698 | G7: 46792 | H7: R1 | I7: - | J7: NEANT | K7: 92 | L7: S1 | M7: Annuelle | N7: 45658 | O7: 2 MOIS | P7: 45709 | Q7: =896.62/AA7 -> 1793.24 | R7: 45708 | S7: 45762 | T7: BDG | U7: 0 | V7: 282 | W7: 0 | Y7: =V7/AD7*100 -> 36.525186 | Z7: 1 | AA7: 0.5 | AB7: 45708 | AC7: =Q7 -> 1793.24 | AD7: 772.07
A8: 1 | B8: A1 | C8: I91 | D8: PEUGEOT 208 5CV PURETECH 100 ACT | E8: P1 | F8: 45698 | G8: 46792 | H8: R1 | I8: - | J8: NEANT | K8: 91 | L8: S1 | M8: Annuelle | N8: 45658 | O8: 2 MOIS | P8: 45671 | Q8: =940.67/AA8 -> 1881.34 | R8: 45670 | AA8: 0.5 | AB8: 45670 | AC8: =Q8 -> 1881.34 | AD8: 907.22
A9: 1 | B9: A1 | C9: I90 | D9: PEUGEOT 208 5CV PURETECH 100 ACT | E9: P1 | F9: 45698 | G9: 46792 | H9: R1 | I9: - | J9: NEANT | K9: 90 | L9: S1 | M9: Annuelle | N9: 45658 | O9: 2 MOIS | P9: 45671 | Q9: =940.67/AA9 -> 1881.34 | R9: 45670 | AA9: 0.5 | AB9: 45670 | AC9: =Q9 -> 1881.34 | AD9: 907.22
A10: 1 | B10: A1 | C10: I89 | D10: PEUGEOT 308 7CV HYBRID 136 ACTIV | E10: P1 | F10: 45698 | G10: 46792 | H10: R1 | I10: C89 | J10: NEANT | K10: 89 | L10: S1 | M10: Annuelle | N10: 45658 | O10: 2 MOIS | P10: 45671 | Q10: =1125.68/AA10 -> 2251.36 | R10: 45670 | S10: 45776 | T10: ACC | U10: 100 | V10: 4602 | W10: 658 | Y10: =V10/AD10*100 -> 423.90523 | Z10: 1 | AA10: 0.5 | AB10: 45670 | AC10: =Q10 -> 2251.36 | AD10: 1085.62
A11: 1 | B11: A1 | C11: I88 | D11: PEUGEOT e208 4CV ELECTRIQUE ACTIVE PA | E11: P1 | F11: 45698 | G11: 46792 | H11: R1 | I11: - | J11: NEANT | K11: 88 | L11: S1 | M11: Annuelle | N11: 45658 | O11: 2 MOIS | P11: 45671 | Q11: =921.1/AA11 -> 1842.2 | R11: 45670 | AA11: 0.5 | AB11: 45670 | AC11: =Q11 -> 1842.2 | AD11: 888.36
A12: 1 | B12: A1 | C12: I87 | D12: PEUGEOT 308 SW 7CV HYB.136 GT | E12: P1 | F12: 45644 | G12: 46738 | H12: R1 | I12: C87 | J12: NEANT | K12: 87 | L12: S1 | M12: Annuelle | N12: 45658 | O12: 2 MOIS | P12: 45644 | Q12: - | R12: - | S12: 45966 | T12: COLL | W12: 658 | Y12: =V12/AD12*100 -> 0 | Z12: 1 | AA12: 0.5 | AB12: 45665 | AC12: =AD12/AA12 -> 2274.84 | AD12: 1137.42
A13: 1 | B13: A1 | C13: I86 | D13: PEUGEOT 5008 7CV PURETECH 130A | E13: P2 | F13: 44908 | G13: 46003 | H13: R1 | I13: C86 | J13: NEANT | K13: 86 | L13: S1 | M13: Annuelle | N13: 45658 | O13: 2 MOIS | P13: 45324 | Q13: - | R13: - | AA13: 0.62 | AB13: 45630 | AC13: =AD13/AA13 -> 2159.0968 | AD13: 1338.64
A14: 1 | B14: A1 | C14: I85 | D14: PEUGEOT 308 SW 6CV E-THP 110 ACT | E14: P2 | F14: 44835 | G14: 45929 | H14: R1 | I14: C85 | J14: NEANT | K14: 85 | L14: S1 | M14: Annuelle | N14: 45658 | O14: 2 MOIS | P14: 45435 | Q14: - | R14: - | AA14: 0.5 | AB14: 45630 | AC14: =AD14/AA14 -> 2038.46 | AD14: 1019.23
A15: 1 | B15: A1 | C15: I84 | D15: PEUGEOT 3008 7CV PURETECH 130 S | E15: P1 | F15: 45212 | G15: 46307 | H15: R1 | I15: C84 | J15: NEANT | K15: 84 | L15: S1 | M15: Annuelle | N15: 45658 | O15: 2 MOIS | P15: 45435 | Q15: - | R15: 45880 | AA15: 0.5 | AB15: 45630 | AC15: =AD15/AA15 -> 2215.26 | AD15: 1107.63
AA16: 0.5 | AB16: 45880 | AC16: =AD16/AA16 -> -700.68 | AD16: -350.34
A17: 1 | B17: A1 | C17: I83 | D17: PEUGEOT 208 5CV PURETECH 100 ALL | E17: P2 | F17: 45177 | G17: 46272 | H17: R1 | I17: C83 | J17: NEANT | K17: 83 | L17: S1 | M17: Annuelle | N17: 45658 | O17: 2 MOIS | P17: 45435 | Q17: - | R17: - | AA17: 0.5 | AB17: 45630 | AC17: =AD17/AA17 -> 2239.66 | AD17: 1119.83
A18: 1 | B18: A1 | C18: I82 | D18: PEUGEOT 208 5CV PURETECH 100 ALL | E18: P2 | F18: 45089 | G18: 46184 | H18: R1 | I18: - | J18: NEANT | K18: 82 | L18: S1 | M18: Annuelle | N18: 45658 | O18: 2 MOIS | P18: 45435 | Q18: - | R18: - | AA18: 0.5 | AB18: 45630 | AC18: =AD18/AA18 -> 2336.98 | AD18: 1168.49
A19: 1 | B19: A1 | C19: I81 | D19: PEUGEOT 208 5CV PURTECH 100 ALL | E19: P2 | F19: 45089 | G19: 46184 | H19: R1 | I19: C81 | J19: NEANT | K19: 81 | L19: S1 | M19: Annuelle | N19: 45658 | O19: 2 MOIS | P19: 45435 | Q19: - | R19: - | AA19: 0.5 | AB19: 45630 | AC19: =AD19/AA19 -> 2240.04 | AD19: 1120.02
A20: 1 | B20: A1 | C20: I80 | D20: BMW X3 10CV 20i XD 184 | E20: P3 | F20: 45076 | G20: 46171 | H20: R1 | I20: C80 | J20: NEANT | K20: 80 | L20: S1 | M20: Annuelle | N20: 45658 | O20: 2 MOIS | P20: 45435 | Q20: - | R20: - | AA20: 0.5 | AB20: 45630 | AC20: =AD20/AA20 -> 4577.28 | AD20: 2288.64
A21: 1 | B21: A1 | C21: I79 | D21: PEUGEOT 208 5CV PURETECH 100 ALL | E21: P2 | F21: 45027 | G21: 46122 | H21: R1 | I21: C79 | J21: NEANT | K21: 79 | L21: S1 | M21: Annuelle | N21: 45658 | O21: 2 MOIS | P21: 45435 | Q21: - | R21: - | S21: 45838 | T21: CLIM | U21: 0 | V21: 2194 | W21: 479 | Y21: =V21/AD21*100 -> 181.82873 | Z21: 1 | AA21: 0.5 | AB21: 45630 | AC21: =AD21/AA21 -> 2413.26 | AD21: 1206.63
A22: 1 | B22: A1 | C22: I78 | D22: PEUGEOT 308 SW 6CV E-THP 110 ACT | E22: P2 | F22: 44978 | G22: 46073 | H22: R1 | I22: C78 | J22: NEANT | K22: 78 | L22: S1 | M22: Annuelle | N22: 45658 | O22: 2 MOIS | P22: 45435 | Q22: - | R22: - | AA22: 0.5 | AB22: 45630 | AC22: =AD22/AA22 -> 2117.12 | AD22: 1058.56
A23: 0 | B23: A1 | C23: I77 | D23: PEUGEOT 208 5CV PURETECH 100 ACT | E23: P2 | F23: 44915 | G23: 46010 | H23: R1 | I23: - | J23: NEANT | K23: 77 | L23: S1 | M23: Annuelle | N23: 45658 | O23: 2 MOIS | P23: 44908 | Q23: - | R23: - | S23: 45686 | T23: BDG | U23: 0 | V23: 219 | W23: 0 | Y23: =V23/AD23*100 -> 17.221449 | Z23: 1 | AA23: 0.5 | AB23: 45630 | AC23: =AD23/AA23 -> 2543.34 | AD23: 1271.67 | AE23: 46010
A24: 1 | B24: A1 | C24: I75 | D24: PEUGEOT 208 5CV PURETECH 100 ALL | E24: P2 | F24: 44878 | G24: 45973 | H24: R1 | I24: - | J24: NEANT | K24: 75 | L24: S1 | M24: Annuelle | N24: 45658 | O24: 2 MOIS | P24: 45405 | Q24: - | R24: - | AA24: 0.5 | AB24: 45630 | AC24: =AD24/AA24 -> 2083.2 | AD24: 1041.6
A25: 1 | B25: A1 | C25: I74 | D25: PEUGEOT 208 5CV PURETECH 100 ALL | E25: P2 | F25: 44885 | G25: 45980 | H25: R1 | I25: - | J25: NEANT | K25: 74 | L25: S1 | M25: Annuelle | N25: 45658 | O25: 2 MOIS | P25: 45435 | Q25: - | R25: - | AA25: 0.5 | AB25: 45630 | AC25: =AD25/AA25 -> 2082.9 | AD25: 1041.45
A26: 1 | B26: A1 | C26: I72 | D26: PEUGEOT 208 5CV PURETECH 100 ACT | E26: P2 | F26: 44827 | G26: 45922 | H26: R1 | I26: - | J26: NEANT | K26: 72 | L26: S1 | M26: Annuelle | N26: 45658 | O26: 2 MOIS | P26: 45435 | Q26: - | R26: - | AA26: 0.5 | AB26: 45630 | AC26: =AD26/AA26 -> 2083.62 | AD26: 1041.81
A27: 1 | B27: A1 | C27: I71 | D27: PEUGEOT 208 5CV PURETECH 100 ACT | E27: P2 | F27: 44855 | G27: 45950 | H27: R1 | I27: - | J27: NEANT | K27: 71 | L27: S1 | M27: Annuelle | N27: 45658 | O27: 2 MOIS | P27: 45435 | Q27: - | R27: - | S27: 45920 | T27: ACC | W27: 283 | Y27: =V27/AD27*100 -> 0 | Z27: 1 | AA27: 0.5 | AB27: 45630 | AC27: =AD27/AA27 -> 2313.14 | AD27: 1156.57
A28: 1 | B28: A1 | C28: I70 | D28: PEUGEOT 208 5CV PURETECH 100 ACT | E28: P2 | F28: 44841 | G28: 45936 | H28: R1 | I28: C70 | J28: NEANT | K28: 70 | L28: S1 | M28: Annuelle | N28: 45658 | O28: 2 MOIS | P28: 45435 | Q28: - | R28: - | AA28: 0.5 | AB28: 45630 | AC28: =AD28/AA28 -> 2218.94 | AD28: 1109.47
A29: 0 | B29: A1 | C29: I69 | D29: PEUGEOT 208 5CV PURETECH 100 ACT | E29: P2 | F29: 44840 | G29: 45935 | H29: R1 | I29: - | J29: NEANT | K29: 69 | L29: S1 | M29: Annuelle | N29: 45658 | O29: 2 MOIS | P29: 44839 | Q29: - | R29: - | S29: 45839 | T29: BDG | U29: 0 | V29: 739 | W29: 0 | Y29: =SUM(V29:V30)/AD29*100 -> 140.87601 | Z29: 2 | AA29: 0.5 | AB29: 45630 | AC29: =AD29/AA29 -> 2094.04 | AD29: 1047.02 | AE29: 45970
S30: 45968 | T30: ACC | V30: 736 | W30: 283
A31: 0 | B31: A1 | C31: I68 | D31: PEUGEOT 208 5CV PURETECH 100 ACT | E31: P2 | F31: 44840 | G31: 45935 | H31: R1 | I31: - | J31: NEANT | K31: 68 | L31: S1 | M31: Annuelle | N31: 45658 | O31: 2 MOIS | P31: 44839 | Q31: - | R31: - | AA31: 0.5 | AB31: 45630 | AC31: =AD31/AA31 -> 2093.72 | AD31: 1046.86 | AE31: 45970
A32: 1 | B32: A1 | C32: I65 | D32: PEUGEOT 308 6 CV PURETECH ACT | E32: P2 | F32: 44754 | G32: 45849 | H32: R1 | I32: C65 | J32: NEANT | K32: 65 | L32: S1 | M32: Annuelle | N32: 45658 | O32: 2 MOIS | P32: 45435 | Q32: - | R32: - | AA32: 0.5 | AB32: 45630 | AC32: =AD32/AA32 -> 2309.84 | AD32: 1154.92
A33: 0 | B33: A1 | C33: I64 | D33: PEUGEOT 308 6CV PURETECH 110 AL | E33: P2 | F33: 44750 | G33: 45845 | H33: R1 | I33: - | J33: NEANT | K33: 64 | L33: S1 | M33: Annuelle | N33: 45658 | O33: 2 MOIS | P33: 45435 | Q33: - | R33: - | AA33: 0.5 | AB33: 45630 | AC33: =AD33/AA33 -> 2309.84 | AD33: 1154.92 | AE33: 45938
AA34: 0.5 | AB34: 45939 | AC34: =AD34/AA34 -> -528.26 | AD34: -264.13
A35: 1 | B35: A1 | C35: I63 | D35: PEUGEOT 308 SW PURETECH 110 | E35: P2 | F35: 44760 | G35: 45855 | H35: R1 | I35: C63 | J35: NEANT | K35: 63 | L35: S1 | M35: Annuelle | N35: 45658 | O35: 2 MOIS | P35: 45435 | Q35: - | R35: - | S35: 45712 | T35: BDG | U35: 0 | V35: 154 | W35: 0 | Y35: =SUM(V35:V36)/AD35*100 -> 54.087903 | Z35: 2 | AA35: 0.5 | AB35: 45630 | AC35: =AD35/AA35 -> 2555.1 | AD35: 1277.55
S36: 45880 | T36: ACC | U36: 100 | V36: 537 | W36: 479
A37: 0 | B37: A1 | C37: I62 | D37: PEUGEOT 208 5CV PURETECH 110 AL | E37: P3 | F37: - | G37: - | H37: R1 | I37: - | J37: NEANT | K37: 62 | L37: S1 | M37: Annuelle | N37: 45658 | O37: 2 MOIS | P37: 45435 | Q37: - | R37: - | AA37: 0.5 | AB37: 45630 | AC37: =AD37/AA37 -> 2382.36 | AD37: 1191.18 | AE37: 45847
AA38: 0.5 | AB38: 45904 | AC38: =AD38/AA38 -> -1142 | AD38: -571
A39: 0 | B39: A1 | C39: I61 | D39: PEUGEOT 108 3CV VTI | E39: P3 | F39: - | G39: - | H39: R1 | I39: - | J39: NEANT | K39: 61 | L39: S1 | M39: Annuelle | N39: 45658 | O39: 2 MOIS | P39: 45435 | Q39: - | R39: - | AA39: 0.5 | AB39: 45630 | AC39: =AD39/AA39 -> 2107.42 | AD39: 1053.71 | AE39: 45847
AA40: 0.5 | AB40: 45904 | AC40: =AD40/AA40 -> -1009.56 | AD40: -504.78
...

Sheet AUTO 2024
B1: Assureur | C1: Immatriculation | D1: Modèle | E1: Propriétaire | F1: Leasing | H1: Assurés | I1: Conducteur | J1: Courtier | K1: N° Contrat | L1: Souscripteur | M1: Périodicité | N1: Renouvellement | O1: Préavis | P1: Date de souscription | Q1: Primes contrats TTC | R1: Mémo Carte Verte | S1: Sinistralité | AA1: Coef BM | AB1: Primes TTC | AE1: Résiliation
F2: Début | G2: Fin | S2: Date | T2: Type | U2: R | V2: Coût | W2: Franchises | X2: Autres* | Y2: Ratio % | Z2: Nombre | AB2: Date | AC2: Primes hors BM | AD2: Primes réglées avec BM
A3: 1 | B3: A1 | C3: I87 | D3: PEUGEOT 308 SW 7CV HYB.136 GT | E3: P1 | F3: 45644 | G3: 46738 | H3: R1 | I3: C87 | J3: NEANT | K3: 87 | L3: S1 | M3: Annuelle | N3: 45658 | O3: 2 MOIS | P3: 45644 | Q3: =1077.95/AA3 -> 2155.9 | R3: 45643 | AA3: 0.5 | AB3: 45643 | AC3: =Q3 -> 2155.9 | AD3: 47.32
A4: 1 | B4: A1 | C4: I86 | D4: PEUGEOT 5008 7CV PURETECH 130A | E4: P2 | F4: 44908 | G4: 46003 | H4: R1 | I4: C86 | J4: NEANT | K4: 86 | L4: S1 | M4: Annuelle | N4: 45658 | O4: 2 MOIS | P4: 45324 | Q4: =1022.03/AA4 -> 2044.06 | R4: 45482 | S4: 45551 | T4: COLL | U4: 100 | V4: 4727.07 | W4: 624 | Y4: =V4/SUM(AD4:AD6)*100 -> 518.7286 | Z4: 1 | AA4: 0.5 | AB4: 45324 | AC4: =Q4 -> 2044.06 | AD4: 927.14
AA5: 0.5 | AB5: 45337 | AC5: =Q5*AA5 -> 0 | AD5: -6.47
AA6: 0.5 | AB6: 45435 | AC6: =Q6*AA6 -> 0 | AD6: -9.39
A7: 1 | B7: A1 | C7: I85 | D7: PEUGEOT 308 SW 6CV E-THP 110 ACT | E7: P2 | F7: 44835 | G7: 45929 | H7: R1 | I7: C85 | J7: NEANT | K7: 85 | L7: S1 | M7: Annuelle | N7: 45658 | O7: 2 MOIS | P7: 45239 | Q7: =869.38/AA7 -> 1738.76 | R7: 45482 | S7: 45555 | T7: BDG | U7: 0 | V7: 164.23 | W7: 0 | Y7: =V7/SUM(AD7:AD8)*100 -> 17.056123 | Z7: 1 | AA7: 0.5 | AB7: 45266 | AC7: =AD7/AA7 -> 1937.68 | AD7: 968.84
P8: 45435 | Q8: =959.23/AA8 -> 1918.46 | AA8: 0.5 | AB8: 45435 | AC8: =AD8/AA8 -> -11.92 | AD8: -5.96
A9: 1 | B9: A1 | C9: I84 | D9: PEUGEOT 3008 7CV PURETECH 130 S | E9: P1 | F9: 45212 | G9: 46307 | H9: R1 | I9: C84 | J9: NEANT | K9: 84 | L9: S1 | M9: Annuelle | N9: 45658 | O9: 2 MOIS | P9: 45212 | Q9: 1711.25 | R9: - | AA9: 0.5 | AB9: 45266 | AC9: =AD9/AA9 -> 2084.46 | AD9: 1042.23
P10: 45435 | Q10: =1048.63/AA10 -> 2097.26 | AA10: 0.5 | AB10: 45435 | AC10: =AD10/AA10 -> 7.86 | AD10: 3.93
A11: 1 | B11: A1 | C11: I83 | D11: PEUGEOT 208 5CV PURETECH 100 ALL | E11: P2 | F11: 45177 | G11: 46272 | H11: R1 | I11: C83 | J11: NEANT | K11: 83 | L11: S1 | M11: Annuelle | N11: 45658 | O11: 2 MOIS | P11: 45145 | Q11: =952.77/AA11 -> 1905.54 | R11: 45482 | S11: 45555 | T11: BDG | U11: 0 | V11: 613.25 | W11: 0 | Y11: =V11/SUM(AD11:AD12)*100 -> 57.907311 | Z11: 1 | AA11: 0.5 | AB11: 45266 | AC11: =AD11/AA11 -> 2111.56 | AD11: 1055.78
P12: 45435 | Q12: =1061.07/AA12 -> 2122.14 | AA12: 0.5 | AB12: 45435 | AC12: =AD12/AA12 -> 6.48 | AD12: 3.24
A13: 1 | B13: A1 | C13: I82 | D13: PEUGEOT 208 5CV PURETECH 100 ALL | E13: P2 | F13: 45089 | G13: 46184 | H13: R1 | I13: - | J13: NEANT | K13: 82 | L13: S1 | M13: Annuelle | N13: 45658 | O13: 2 MOIS | P13: 45119 | Q13: =953.19/AA13 -> 1906.38 | R13: 45482 | S13: 45424 | T13: ACC | U13: 0 | V13: 1500.79 | W13: 454 | Y13: =V13/SUM(AD13:AD14)*100 -> 141.68154 | Z13: 1 | AA13: 0.5 | AB13: 45266 | AC13: =AD13/AA13 -> 2112.4 | AD13: 1056.2
P14: 45435 | Q14: =1061.25/AA14 -> 2122.5 | AA14: 0.5 | AB14: 45435 | AC14: =AD14/AA14 -> 6.14 | AD14: 3.07
A15: 1 | B15: A1 | C15: I81 | D15: PEUGEOT 208 5CV PURTECH 100 ALL | E15: P2 | F15: 45089 | G15: 46184 | H15: R1 | I15: C81 | J15: NEANT | K15: 81 | L15: S1 | M15: Annuelle | N15: 45658 | O15: 2 MOIS | P15: 45119 | Q15: =953.19/AA15 -> 1906.38 | R15: 45482 | AA15: 0.5 | AB15: 45266 | AC15: =AD15/AA15 -> 2112.4 | AD15: 1056.2
P16: 45435 | Q16: =1061.25/AA16 -> 2122.5 | AA16: 0.5 | AB16: 45435 | AC16: =AD16/AA16 -> 6.14 | AD16: 3.07
A17: 1 | B17: A1 | C17: I80 | D17: BMW X3 10CV 20i XD 184 | E17: P3 | F17: 45076 | G17: 46171 | H17: R1 | I17: C80 | J17: NEANT | K17: 80 | L17: S1 | M17: Annuelle | N17: 45658 | O17: 2 MOIS | P17: 45072 | Q17: =1831.04/AA17 -> 3662.08 | R17: 45482 | S17: 45425 | T17: ACC | U17: 0 | V17: 1365.9 | W17: 676 | Y17: =SUM(V17:V18)/SUM(AD17:AD18)*100 -> 80.513284 | Z17: 2 | AA17: 0.5 | AB17: 45266 | AC17: =AD17/AA17 -> 4096.7 | AD17: 2048.35
P18: 45435 | Q18: =2026.66/AA18 -> 4053.32 | S18: 45432 | T18: BDG | U18: 0 | V18: 272.65 | W18: 0 | AA18: 0.5 | AB18: 45435 | AC18: =AD18/AA18 -> -26.44 | AD18: -13.22
A19: 1 | B19: A1 | C19: I79 | D19: PEUGEOT 208 5CV PURETECH 100 ALL | E19: P2 | F19: 45027 | G19: 46122 | H19: R1 | I19: C79 | J19: NEANT | K19: 79 | L19: S1 | M19: Annuelle | N19: 45658 | O19: 2 MOIS | P19: 45027 | Q19: =1036.99/AA19 -> 2073.98 | R19: 45482 | AA19: 0.5 | AB19: 45266 | AC19: =AD19/AA19 -> 2298.62 | AD19: 1149.31
P20: 45435 | Q20: =1143.3/AA20 -> 2286.6 | AA20: 0.5 | AB20: 45435 | AC20: =AD20/AA20 -> -7.32 | AD20: -3.66
A21: 1 | B21: A1 | C21: I78 | D21: PEUGEOT 308 SW 6CV E-THP 110 ACT | E21: P2 | F21: 44978 | G21: 46073 | H21: R1 | I21: C78 | J21: NEANT | K21: 78 | L21: S1 | M21: Annuelle | N21: 45658 | O21: 2 MOIS | P21: 45239 | Q21: =869.38/AA21 -> 1738.76 | R21: 45482 | AA21: 0.5 | AB21: 45266 | AC21: =AD21/AA21 -> 2016.34 | AD21: 1008.17
P22: 45435 | Q22: =1002.41/AA22 -> 2004.82 | AA22: 0.5 | AB22: 45435 | AC22: =AD22/AA22 -> -7.06 | AD22: -3.53
A23: 1 | B23: A1 | C23: I77 | D23: PEUGEOT 208 5CV PURETECH 100 ACT | E23: P2 | F23: 44915 | G23: 46010 | H23: R1 | I23: - | J23: NEANT | K23: 77 | L23: S1 | M23: Annuelle | N23: 45658 | O23: 2 MOIS | P23: 44908 | Q23: =883.91/AA23 -> 1767.82 | R23: 45482 | S23: 45541 | T23: ACC | U23: 100 | V23: 1422.25 | W23: 454 | Y23: =V23/AD23*100 -> 130.63266 | Z23: 1 | AA23: 0.5 | AB23: 45266 | AC23: =AD23/AA23 -> 2177.48 | AD23: 1088.74
A24: 0 | B24: A1 | C24: I76 | H24: R1 | I24: C76 | J24: NEANT | K24: 76 | L24: S1 | M24: Annuelle | N24: 46023 | O24: 2 MOIS | AE24: 45324
A25: 1 | B25: A1 | C25: I75 | D25: PEUGEOT 208 5CV PURETECH 100 ALL | E25: P2 | F25: 44878 | G25: 45973 | H25: R1 | I25: - | J25: NEANT | K25: 75 | L25: S1 | M25: Annuelle | N25: 45658 | O25: 2 MOIS | P25: 44873 | Q25: =797.04/AA25 -> 1594.08 | R25: 45482 | S25: 45342 | T25: BDG | U25: 0 | V25: 236.67 | W25: 0 | Y25: =SUM(V25:V26)/SUM(AD25:AD26)*100 -> 30.705684 | Z25: 2 | AA25: 0.5 | AB25: 45266 | AC25: =AD25/AA25 -> 1984.56 | AD25: 992.28
P26: 45435 | Q26: =986.86/AA26 -> 1973.72 | S26: 45545 | T26: BDG | U26: 0 | V26: 67 | W26: 0 | AA26: 0.5 | AB26: 45435 | AC26: =AD26/AA26 -> -6.62 | AD26: -3.31
A27: 1 | B27: A1 | C27: I74 | D27: PEUGEOT 208 5CV PURETECH 100 ALL | E27: P2 | F27: 44885 | G27: 45980 | H27: R1 | I27: - | J27: NEANT | K27: 74 | L27: S1 | M27: Annuelle | N27: 45658 | O27: 2 MOIS | P27: 44873 | Q27: =797.04/AA27 -> 1594.08 | R27: 45482 | S27: 45637 | T27: BDG | U27: 0 | V27: 244.2 | W27: 0 | Y27: =V27/SUM(AD27:AD28)*100 -> 24.692357 | Z27: 1 | AA27: 0.5 | AB27: 45266 | AC27: =AD27/AA27 -> 1984.56 | AD27: 992.28
P28: 45435 | Q28: =986.86/AA28 -> 1973.72 | AA28: 0.5 | AB28: 45435 | AC28: =AD28/AA28 -> -6.62 | AD28: -3.31
A29: 1 | B29: A1 | C29: I72 | D29: PEUGEOT 208 5CV PURETECH 100 ACT | E29: P2 | F29: 44827 | G29: 45922 | H29: R1 | I29: - | J29: NEANT | K29: 72 | L29: S1 | M29: Annuelle | N29: 45658 | O29: 2 MOIS | P29: 44868 | Q29: =788.8/AA29 -> 1577.6 | R29: 45482 | AA29: 0.5 | AB29: 45266 | AC29: =AD29/AA29 -> 1965.38 | AD29: 982.69
P30: 45435 | Q30: =987.2/AA30 -> 1974.4 | AA30: 0.5 | AB30: 45435 | AC30: =AD30/AA30 -> 5.48 | AD30: 2.74
A31: 1 | B31: A1 | C31: I71 | D31: PEUGEOT 208 5CV PURETECH 100 ACT | E31: P2 | F31: 44855 | G31: 45950 | H31: R1 | I31: - | J31: NEANT | K31: 71 | L31: S1 | M31: Annuelle | N31: 45658 | O31: 2 MOIS | P31: 44840 | Q31: =771.96/AA31 -> 1543.92 | R31: 45482 | S31: 45462 | T31: COLL | U31: 100 | V31: 5297 | W31: 268 | Y31: =SUM(V31:V32)/SUM(AD31:AD32)*100 -> 626.1374 | Z31: 2 | AA31: 0.5 | AB31: 45266 | AC31: =AD31/AA31 -> 1923.48 | AD31: 961.74
P32: 45435 | Q32: =966.24/AA32 -> 1932.48 | S32: 45622 | T32: BDG | U32: 0 | V32: 741.97 | W32: 0 | AA32: 0.5 | AB32: 45435 | AC32: =AD32/AA32 -> 5.48 | AD32: 2.74
A33: 1 | B33: A1 | C33: I70 | D33: PEUGEOT 208 5CV PURETECH 100 ACT | E33: P2 | F33: 44841 | G33: 45936 | H33: R1 | I33: C70 | J33: NEANT | K33: 70 | L33: S1 | M33: Annuelle | N33: 45658 | O33: 2 MOIS | P33: 44841 | Q33: =881.27/AA33 -> 1762.54 | R33: 45482 | AA33: 0.5 | AB33: 45266 | AC33: =AD33/AA33 -> 2113.08 | AD33: 1056.54
P34: 45435 | Q34: =1051.36/AA34 -> 2102.72 | AA34: 0.5 | AB34: 45435 | AC34: =AD34/AA34 -> -6.3 | AD34: -3.15
A35: 1 | B35: A1 | C35: I69 | D35: PEUGEOT 208 5CV PURETECH 100 ACT | E35: P2 | F35: 44840 | G35: 45935 | H35: R1 | I35: - | J35: NEANT | K35: 69 | L35: S1 | M35: Annuelle | N35: 45658 | O35: 2 MOIS | P35: 44839 | Q35: =795.9/AA35 -> 1591.8 | R35: 45482 | AA35: 0.5 | AB35: 45266 | AC35: =AD35/AA35 -> 1983.9 | AD35: 991.95
A36: 1 | B36: A1 | C36: I68 | D36: PEUGEOT 208 5CV PURETECH 100 ACT | E36: P2 | F36: 44840 | G36: 45935 | H36: R1 | I36: - | J36: NEANT | K36: 68 | L36: S1 | M36: Annuelle | N36: 45658 | O36: 2 MOIS | P36: 44839 | Q36: =795.9/AA36 -> 1591.8 | R36: 45482 | AA36: 0.5 | AB36: 45266 | AC36: =AD36/AA36 -> 1983.94 | AD36: 991.97
A37: 1 | B37: A1 | C37: I65 | D37: PEUGEOT 308 6 CV PURETECH ACT | E37: P2 | F37: 44754 | G37: 45849 | H37: R1 | I37: C65 | J37: NEANT | K37: 65 | L37: S1 | M37: Annuelle | N37: 45658 | O37: 2 MOIS | P37: 44754 | Q37: =881.27/AA37 -> 1762.54 | R37: 45482 | AA37: 0.5 | AB37: 45266 | AC37: =AD37/AA37 -> 2201.24 | AD37: 1100.62
P38: 45435 | Q38: =1094.19/AA38 -> 2188.38 | AA38: 0.5 | AB38: 45435 | AC38: =AD38/AA38 -> -7.8 | AD38: -3.9
A39: 1 | B39: A1 | C39: I64 | D39: PEUGEOT 308 6CV PURETECH 110 AL | E39: P2 | F39: 44750 | G39: 45845 | H39: R1 | I39: - | J39: NEANT | K39: 64 | L39: S1 | M39: Annuelle | N39: 45658 | O39: 2 MOIS | P39: 44750 | Q39: =881.27/AA39 -> 1762.54 | R39: 45482 | AA39: 0.5 | AB39: 45266 | AC39: =AD39/AA39 -> 2201.24 | AD39: 1100.62
P40: 45435 | Q40: =1094.19/AA40 -> 2188.38 | AA40: 0.5 | AB40: 45435 | AC40: =AD40/AA40 -> -7.8 | AD40: -3.9
...

Sheet FLOTTE
D1: 2024 | J1: 2025 | N1: 2026
B2: Conducteur | C2: Immatriculation | D2: Coût | E2: Franchises | F2: Primes annuelles N-X | G2: Primes annuelles N | H2: Primes hors B/M | I2: Primes avec B/M | J2: Coût | K2: Franchises | L2: Primes hors B/M | M2: Primes avec B/M | N2: Coût | O2: Franchises | P2: Primes hors B/M | Q2: Primes avec B/M
A3: 1 | B3: - | C3: I97 | P3: ='AUTO 2026'!AC3 -> 2000.46 | Q3: ='AUTO 2026'!AD3 -> 1000.23
A4: 1 | B4: C96 | C4: I96 | J4: ='[1]AUTO 2025'!V3 -> 194.16 | K4: =SUM('[1]AUTO 2025'!W3) -> 0 | L4: ='AUTO 2025'!Q3 -> 1430.4 | M4: =L4*'AUTO 2025'!AA3 -> 715.2 | P4: ='AUTO 2026'!AC4 -> 1505.3 | Q4: ='AUTO 2026'!AD4 -> 752.65
A5: 1 | B5: - | C5: I95 | L5: ='AUTO 2025'!Q4 -> 1793.24 | M5: =L5*'AUTO 2025'!AA4 -> 896.62 | P5: ='AUTO 2026'!AC5 -> 1874.94 | Q5: ='AUTO 2026'!AD5 -> 937.47
A6: 1 | B6: - | C6: I94 | L6: ='AUTO 2025'!Q5 -> 1793.24 | M6: =L6*'AUTO 2025'!AA5 -> 896.62 | P6: ='AUTO 2026'!AC6 -> 1874.94 | Q6: ='AUTO 2026'!AD6 -> 937.47
A7: 1 | B7: - | C7: I93 | J7: ='[1]AUTO 2025'!V6 -> 235 | K7: =SUM('[1]AUTO 2025'!W6) -> 0 | L7: ='AUTO 2025'!Q6 -> 1793.24 | M7: =L7*'AUTO 2025'!AA6 -> 896.62 | P7: ='AUTO 2026'!AC7 -> 1874.94 | Q7: ='AUTO 2026'!AD7 -> 937.47
A8: 1 | B8: - | C8: I92 | J8: ='[1]AUTO 2025'!V7 -> 282 | K8: =SUM('[1]AUTO 2025'!W7) -> 0 | L8: ='AUTO 2025'!Q7 -> 1793.24 | M8: =L8*'AUTO 2025'!AA7 -> 896.62 | P8: ='AUTO 2026'!AC8 -> 1874.94 | Q8: ='AUTO 2026'!AD8 -> 937.47
A9: 1 | B9: - | C9: I91 | L9: ='AUTO 2025'!Q8 -> 1881.34 | M9: =L9*'AUTO 2025'!AA8 -> 940.67 | P9: ='AUTO 2026'!AC9 -> 1977.82 | Q9: ='AUTO 2026'!AD9 -> 988.91
A10: 1 | B10: - | C10: I90 | L10: ='AUTO 2025'!Q9 -> 1881.34 | M10: =L10*'AUTO 2025'!AA9 -> 940.67 | P10: ='AUTO 2026'!AC10 -> 1977.82 | Q10: ='AUTO 2026'!AD10 -> 988.91
A11: 1 | B11: C89 | C11: I89 | J11: ='[1]AUTO 2025'!V10 -> 4602 | K11: =SUM('[1]AUTO 2025'!W10) -> 658 | L11: ='AUTO 2025'!Q10 -> 2251.36 | M11: =L11*'AUTO 2025'!AA10 -> 1125.68 | P11: ='AUTO 2026'!AC11 -> 2530.38 | Q11: ='AUTO 2026'!AD11 -> 1265.19
A12: 1 | B12: - | C12: I88 | L12: ='AUTO 2025'!Q11 -> 1842.2 | M12: =L12*'AUTO 2025'!AA11 -> 921.1 | P12: ='AUTO 2026'!AC12 -> 1927.78 | Q12: ='AUTO 2026'!AD12 -> 963.89
A13: 1 | B13: C87 | C13: I87 | H13: ='AUTO 2024'!AC3 -> 2155.9 | I13: =H13*'AUTO 2024'!AA3 -> 1077.95 | J13: ='[1]AUTO 2025'!V12 -> 0 | K13: =SUM('[1]AUTO 2025'!W12) -> 658 | L13: ='AUTO 2025'!AC12 -> 2274.84 | M13: ='AUTO 2025'!AD12 -> 1137.42 | P13: ='AUTO 2026'!AC13 -> 2383.36 | Q13: ='AUTO 2026'!AD13 -> 1191.68
A14: 1 | B14: C86 | C14: I86 | D14: =SUM('[1]AUTO 2024'!V4:V6) -> 4727.07 | E14: =SUM('[1]AUTO 2024'!W4:W6) -> 624 | H14: =SUM('AUTO 2024'!AC4:AC6) -> 2044.06 | I14: =H14*'AUTO 2024'!AA4 -> 1022.03 | L14: ='AUTO 2025'!AC13 -> 2159.0968 | M14: ='AUTO 2025'!AD13 -> 1338.64 | P14: ='AUTO 2026'!AC14 -> 2375.6379 | Q14: ='AUTO 2026'!AD14 -> 1377.87
A15: 1 | B15: C85 | C15: I85 | D15: =SUM('[1]AUTO 2024'!V7:V8) -> 164.23 | E15: =SUM('[1]AUTO 2024'!W7:W8) -> 0 | F15: ='AUTO 2024'!Q7 -> 1738.76 | G15: ='AUTO 2024'!Q8 -> 1918.46 | H15: =SUM('AUTO 2024'!AC7:AC8) -> 1925.76 | I15: =SUM('AUTO 2024'!AD7:AD8) -> 962.88 | L15: ='AUTO 2025'!AC14 -> 2038.46 | M15: ='AUTO 2025'!AD14 -> 1019.23 | N15: ='[1]AUTO 2026'!V15 -> 0 | O15: =SUM('[1]AUTO 2026'!W15) -> 0 | P15: ='AUTO 2026'!AC15 -> 2144.58 | Q15: ='AUTO 2026'!AD15 -> 1072.29
A16: 1 | B16: C84 | C16: I84 | F16: ='AUTO 2024'!Q9 -> 1711.25 | G16: ='AUTO 2024'!Q10 -> 2097.26 | H16: =SUM('AUTO 2024'!AC9:AC10) -> 2092.32 | I16: =SUM('AUTO 2024'!AD9:AD10) -> 1046.16 | L16: ='AUTO 2025'!AC15 -> 2215.26 | M16: ='AUTO 2025'!AD15 -> 1107.63
A17: 1 | B17: C83 | C17: I83 | D17: =SUM('[1]AUTO 2024'!V11:V12) -> 613.25 | E17: =SUM('[1]AUTO 2024'!W11:W12) -> 0 | F17: ='AUTO 2024'!Q11 -> 1905.54 | G17: ='AUTO 2024'!Q12 -> 2122.14 | H17: =SUM('AUTO 2024'!AC11:AC12) -> 2118.04 | I17: =SUM('AUTO 2024'!AD11:AD12) -> 1059.02 | L17: ='AUTO 2025'!AC17 -> 2239.66 | M17: ='AUTO 2025'!AD17 -> 1119.83 | P17: ='AUTO 2026'!AC16 -> 2331.16 | Q17: ='AUTO 2026'!AD16 -> 1165.58
A18: 1 | B18: - | C18: I82 | D18: =SUM('[1]AUTO 2024'!V13:V14) -> 1500.79 | E18: =SUM('[1]AUTO 2024'!W13:W14) -> 454 | F18: ='AUTO 2024'!Q13 -> 1906.38 | G18: ='AUTO 2024'!Q14 -> 2122.5 | H18: =SUM('AUTO 2024'!AC13:AC14) -> 2118.54 | I18: =SUM('AUTO 2024'!AD13:AD14) -> 1059.27 | L18: ='AUTO 2025'!AC18 -> 2336.98 | M18: ='AUTO 2025'!AD18 -> 1168.49 | P18: ='AUTO 2026'!AC17 -> 2432.28 | Q18: ='AUTO 2026'!AD17 -> 1216.14
A19: 1 | B19: C81 | C19: I81 | F19: ='AUTO 2024'!Q15 -> 1906.38 | G19: ='AUTO 2024'!Q16 -> 2122.5 | H19: =SUM('AUTO 2024'!AC15:AC16) -> 2118.54 | I19: =SUM('AUTO 2024'!AD15:AD16) -> 1059.27 | L19: ='AUTO 2025'!AC19 -> 2240.04 | M19: ='AUTO 2025'!AD19 -> 1120.02 | P19: ='AUTO 2026'!AC18 -> 2331.9 | Q19: ='AUTO 2026'!AD18 -> 1165.95
A20: 1 | B20: C80 | C20: I80 | D20: =SUM('[1]AUTO 2024'!V17:V18) -> 1638.55 | E20: =SUM('[1]AUTO 2024'!W17:W18) -> 676 | F20: ='AUTO 2024'!Q17 -> 3662.08 | G20: ='AUTO 2024'!Q18 -> 4053.32 | H20: =SUM('AUTO 2024'!AC17:AC18) -> 4070.26 | I20: =SUM('AUTO 2024'!AD17:AD18) -> 2035.13 | L20: ='AUTO 2025'!AC20 -> 4577.28 | M20: ='AUTO 2025'!AD20 -> 2288.64 | P20: ='AUTO 2026'!AC19 -> 4770.76 | Q20: ='AUTO 2026'!AD19 -> 2385.38
A21: 1 | B21: C79 | C21: I79 | F21: ='AUTO 2024'!Q19 -> 2073.98 | G21: ='AUTO 2024'!Q20 -> 2286.6 | H21: =SUM('AUTO 2024'!AC19:AC20) -> 2291.3 | I21: =SUM('AUTO 2024'!AD19:AD20) -> 1145.65 | J21: ='[1]AUTO 2025'!V21 -> 2194 | K21: =SUM('[1]AUTO 2025'!W21) -> 479 | L21: ='AUTO 2025'!AC21 -> 2413.26 | M21: ='AUTO 2025'!AD21 -> 1206.63 | P21: ='AUTO 2026'!AC20 -> 2510.92 | Q21: ='AUTO 2026'!AD20 -> 1255.46
A22: 1 | B22: C78 | C22: I78 | F22: ='AUTO 2024'!Q21 -> 1738.76 | G22: ='AUTO 2024'!Q22 -> 2004.82 | H22: =SUM('AUTO 2024'!AC21:AC22) -> 2009.28 | I22: =SUM('AUTO 2024'!AD21:AD22) -> 1004.64 | L22: ='AUTO 2025'!AC22 -> 2117.12 | M22: ='AUTO 2025'!AD22 -> 1058.56 | P22: ='AUTO 2026'!AC21 -> 2214.76 | Q22: ='AUTO 2026'!AD21 -> 1107.38
A23: 1 | B23: - | C23: I77 | D23: =SUM('[1]AUTO 2024'!V23) -> 1422.25 | E23: =SUM('[1]AUTO 2024'!W23) -> 454 | F23: ='AUTO 2024'!Q23 -> 1767.82 | H23: =SUM('AUTO 2024'!AC23) -> 2177.48 | I23: =SUM('AUTO 2024'!AD23) -> 1088.74 | J23: ='[1]AUTO 2025'!V23 -> 219 | K23: =SUM('[1]AUTO 2025'!W23) -> 0 | L23: ='AUTO 2025'!AC23 -> 2543.34 | M23: ='AUTO 2025'!AD23 -> 1271.67 | P23: ='AUTO 2026'!AC22 -> 2672.02 | Q23: ='AUTO 2026'!AD22 -> 1336.01
A24: 1 | B24: - | C24: I75 | D24: =SUM('[1]AUTO 2024'!V25:V26) -> 303.67 | E24: =SUM('[1]AUTO 2024'!W25:W26) -> 0 | F24: ='AUTO 2024'!Q25 -> 1594.08 | G24: ='AUTO 2024'!Q26 -> 1973.72 | H24: =SUM('AUTO 2024'!AC25:AC26) -> 1977.94 | I24: =SUM('AUTO 2024'!AD25:AD26) -> 988.97 | L24: ='AUTO 2025'!AC24 -> 2083.2 | M24: ='AUTO 2025'!AD24 -> 1041.6 | P24: ='AUTO 2026'!AC24 -> 2170.26 | Q24: ='AUTO 2026'!AD24 -> 1085.13
A25: 1 | B25: - | C25: I74 | D25: =SUM('[1]AUTO 2024'!V27:V28) -> 244.2 | E25: =SUM('[1]AUTO 2024'!W27:W28) -> 0 | F25: ='AUTO 2024'!Q27 -> 1594.08 | G25: ='AUTO 2024'!Q28 -> 1973.72 | H25: =SUM('AUTO 2024'!AC27:AC28) -> 1977.94 | I25: =SUM('AUTO 2024'!AD27:AD28) -> 988.97 | L25: ='AUTO 2025'!AC25 -> 2082.9 | M25: ='AUTO 2025'!AD25 -> 1041.45 | P25: ='AUTO 2026'!AC25 -> 2190.82 | Q25: ='AUTO 2026'!AD25 -> 1095.41
A26: 1 | B26: - | C26: I72 | F26: ='AUTO 2024'!Q29 -> 1577.6 | G26: ='AUTO 2024'!Q30 -> 1974.4 | H26: =SUM('AUTO 2024'!AC29:AC30) -> 1970.86 | I26: =SUM('AUTO 2024'!AD29:AD30) -> 985.43 | L26: ='AUTO 2025'!AC26 -> 2083.62 | M26: ='AUTO 2025'!AD26 -> 1041.81 | P26: ='AUTO 2026'!AC26 -> 2177.46 | Q26: ='AUTO 2026'!AD26 -> 1088.73
A27: 1 | B27: - | C27: I71 | D27: =SUM('[1]AUTO 2024'!V31:V32) -> 6038.97 | E27: =SUM('[1]AUTO 2024'!W31:W32) -> 268 | F27: ='AUTO 2024'!Q31 -> 1543.92 | G27: ='AUTO 2024'!Q32 -> 1932.48 | H27: =SUM('AUTO 2024'!AC31:AC32) -> 1928.96 | I27: =SUM('AUTO 2024'!AD31:AD32) -> 964.48 | J27: ='[1]AUTO 2025'!V27 -> 0 | K27: =SUM('[1]AUTO 2025'!W27) -> 283 | L27: ='AUTO 2025'!AC27 -> 2313.14 | M27: ='AUTO 2025'!AD27 -> 1156.57 | P27: ='AUTO 2026'!AC27 -> 2419.74 | Q27: ='AUTO 2026'!AD27 -> 1209.87
A28: 1 | B28: C70 | C28: I70 | F28: ='AUTO 2024'!Q33 -> 1762.54 | G28: ='AUTO 2024'!Q34 -> 2102.72 | H28: =SUM('AUTO 2024'!AC33:AC34) -> 2106.78 | I28: =SUM('AUTO 2024'!AD33:AD34) -> 1053.39 | L28: ='AUTO 2025'!AC28 -> 2218.94 | M28: ='AUTO 2025'!AD28 -> 1109.47 | P28: ='AUTO 2026'!AC28 -> 2318.52 | Q28: ='AUTO 2026'!AD28 -> 1159.26
A29: 1 | B29: - | C29: I69 | F29: ='AUTO 2024'!Q35 -> 1591.8 | H29: ='AUTO 2024'!AC35 -> 1983.9 | I29: =SUM('AUTO 2024'!AD35) -> 991.95 | J29: =SUM('[1]AUTO 2025'!V29:V30) -> 1475 | K29: =SUM('[1]AUTO 2025'!W29:W30) -> 283 | L29: ='AUTO 2025'!AC29 -> 2094.04 | M29: ='AUTO 2025'!AD29 -> 1047.02 | P29: ='AUTO 2026'!AC29 -> 2183.9 | Q29: ='AUTO 2026'!AD29 -> 1091.95
A30: 1 | B30: - | C30: I68 | F30: ='AUTO 2024'!Q36 -> 1591.8 | H30: ='AUTO 2024'!AC36 -> 1983.94 | I30: =SUM('AUTO 2024'!AD36) -> 991.97 | L30: ='AUTO 2025'!AC31 -> 2093.72 | M30: ='AUTO 2025'!AD31 -> 1046.86 | P30: ='AUTO 2026'!AC31 -> 2183.28 | Q30: ='AUTO 2026'!AD31 -> 1091.64
A31: 1 | B31: C65 | C31: I65 | F31: ='AUTO 2024'!Q37 -> 1762.54 | G31: ='AUTO 2024'!Q38 -> 2188.38 | H31: =SUM('AUTO 2024'!AC37:AC38) -> 2193.44 | I31: =SUM('AUTO 2024'!AD37:AD38) -> 1096.72 | L31: ='AUTO 2025'!AC32 -> 2309.84 | M31: ='AUTO 2025'!AD32 -> 1154.92 | P31: ='AUTO 2026'!AC33 -> 2407.44 | Q31: ='AUTO 2026'!AD33 -> 1203.72
A32: 1 | B32: - | C32: I64 | F32: ='AUTO 2024'!Q39 -> 1762.54 | G32: ='AUTO 2024'!Q40 -> 2188.38 | H32: =SUM('AUTO 2024'!AC39:AC40) -> 2193.44 | I32: =SUM('AUTO 2024'!AD39:AD40) -> 1096.72 | L32: ='AUTO 2025'!AC33 -> 2309.84 | M32: ='AUTO 2025'!AD33 -> 1154.92
A33: 1 | B33: C63 | C33: I63 | D33: =SUM('[1]AUTO 2024'!V41:V42) -> 1486.36 | E33: =SUM('[1]AUTO 2024'!W41:W42) -> 908 | F33: ='AUTO 2024'!Q41 -> 1753.32 | G33: ='AUTO 2024'!Q42 -> 2142.54 | H33: =SUM('AUTO 2024'!AC41:AC42) -> 2147.34 | I33: =SUM('AUTO 2024'!AD41:AD42) -> 1073.67 | J33: =SUM('[1]AUTO 2025'!V35:V36) -> 691 | K33: =SUM('[1]AUTO 2025'!W35:W36) -> 479 | L33: ='AUTO 2025'!AC35 -> 2555.1 | M33: ='AUTO 2025'!AD35 -> 1277.55 | P33: ='AUTO 2026'!AC34 -> 2946.3871 | Q33: ='AUTO 2026'!AD34 -> 1826.76
A34: 1 | B34: - | C34: I62 | D34: =SUM('[1]AUTO 2024'!V43) -> 572.06 | E34: =SUM('[1]AUTO 2024'!W43) -> 0 | F34: ='AUTO 2024'!Q43 -> 1715.22 | G34: ='AUTO 2024'!Q44 -> 2257.3 | H34: =SUM('AUTO 2024'!AC43:AC44) -> 2252.66 | I34: =SUM('AUTO 2024'!AD43:AD44) -> 1126.33 | L34: ='AUTO 2025'!AC37 -> 2382.36 | M34: ='AUTO 2025'!AD37 -> 1191.18
A35: 1 | B35: - | C35: I61 | F35: ='AUTO 2024'!Q45 -> 1497.48 | G35: ='AUTO 2024'!Q46 -> 1997 | H35: =SUM('AUTO 2024'!AC45:AC46) -> 1992.6 | I35: =SUM('AUTO 2024'!AD45:AD46) -> 996.3 | J35: =SUM('[1]AUTO 2025'!V41:V43) -> 635 | K35: =SUM('[1]AUTO 2025'!W41:W43) -> 479 | L35: ='AUTO 2025'!AC39 -> 2107.42 | M35: ='AUTO 2025'!AD39 -> 1053.71
A36: 1 | B36: - | C36: FM-682-JX | D36: =SUM('[1]AUTO 2024'!V47:V48) -> 222.46 | E36: =SUM('[1]AUTO 2024'!W47) -> 0 | F36: ='AUTO 2024'!Q47 -> 1529.98 | G36: ='AUTO 2024'!Q48 -> 2111.14 | H36: =SUM('AUTO 2024'!AC47:AC48) -> 2112.74 | I36: =SUM('AUTO 2024'!AD47:AD48) -> 1056.37 | L36: ='AUTO 2025'!AC41 -> 2230.24 | M36: ='AUTO 2025'!AD41 -> 1115.12
A37: 1 | B37: - | C37: FJ-446-CM | F37: ='AUTO 2024'!Q49 -> 1382.2 | G37: ='AUTO 2024'!Q50 -> 1906.42 | H37: =SUM('AUTO 2024'!AC49:AC50) -> 1907.36 | I37: =SUM('AUTO 2024'!AD49:AD50) -> 953.68 | L37: ='AUTO 2025'!AC44 -> 2014.44 | M37: ='AUTO 2025'!AD44 -> 1007.22
A38: =SUM(A3:A37) -> 35 | D38: =SUM(D13:D37) -> 18933.86 | E38: =SUM(E13:E37) -> 3384 | F38: =SUM(F13:F37) -> 41070.05 | G38: =SUM(G13:G37) -> 43475.8 | H38: =SUM(H13:H37) -> 53851.38 | I38: =SUM(I13:I37) -> 26925.69 | J38: =SUM(J4:J37) -> 10527.16 | K38: =SUM(K4:K37) -> 3319 | L38: =SUM(L4:L37) -> 74493.737 | M38: =SUM(M4:M37) -> 37505.96 | N38: =SUM(N4:N37) -> 0 | O38: =SUM(O4:O37) -> 0 | P38: =SUM(P3:P37) -> 66584.505 | Q38: =SUM(Q3:Q37) -> 33835.87
A40: BUDGET | B40: ENTREE VEHICULES | H40: =SUM(H13:H14) -> 4199.96 | I40: =SUM(I13:I14) -> 2099.98 | L40: =SUM(L4:L12) -> 16459.6 | M40: =SUM(M4:M12) -> 8229.8 | P40: =P3 -> 2000.46 | Q40: =Q3 -> 1000.23
B41: SORTIES VEHICULES | H41: 0 | I41: 0 | L41: =L16+L32+SUM(L34:L37) -> 13259.56 | M41: =M16+M32+SUM(M34:M37) -> 6629.78 | P41: 0 | Q41: 0
...

Sheet VH FONCTION
D1: 2024 | J1: 2025 | N1: 2026
B2: Conducteur | C2: Immatriculation | D2: Coût | E2: Franchise | F2: Primes annuelles N-X | G2: Primes annuelles N | H2: Primes hors B/M | I2: Primes avec B/M | J2: Coût | K2: Franchise | L2: Primes hors B/M | M2: Primes avec B/M | N2: Coût | O2: Franchise | P2: Primes hors B/M | Q2: Primes avec B/M
A3: 1 | B3: C96 | C3: 96 | J3: ='[1]AUTO 2025'!V3 -> 194.16 | K3: ='[1]AUTO 2025'!W3 -> 0 | L3: ='AUTO 2025'!Q3 -> 1430.4 | M3: =L3*'AUTO 2025'!AA3 -> 715.2 | P3: ='AUTO 2026'!AC4 -> 1505.3 | Q3: ='AUTO 2026'!AD4 -> 752.65
A4: 1 | B4: C89 | C4: I89 | J4: ='[1]AUTO 2025'!V10 -> 4602 | K4: ='[1]AUTO 2025'!W10 -> 658 | L4: ='AUTO 2025'!Q10 -> 2251.36 | M4: =L4*'AUTO 2025'!AA10 -> 1125.68 | P4: ='AUTO 2026'!AC11 -> 2530.38 | Q4: ='AUTO 2026'!AD11 -> 1265.19
A5: 1 | B5: C87 | C5: I87 | H5: ='AUTO 2024'!AC3 -> 2155.9 | I5: =H5*'AUTO 2024'!AA3 -> 1077.95 | J5: ='[1]AUTO 2025'!V12 -> 0 | K5: ='[1]AUTO 2025'!W12 -> 658 | L5: ='AUTO 2025'!AC12 -> 2274.84 | M5: ='AUTO 2025'!AD12 -> 1137.42 | P5: ='AUTO 2026'!AC13 -> 2383.36 | Q5: ='AUTO 2026'!AD13 -> 1191.68
A6: 1 | B6: C86 | C6: I86 | D6: =SUM('[1]AUTO 2024'!V4:V6) -> 4727.07 | E6: =SUM('[1]AUTO 2024'!W4:W6) -> 624 | H6: =SUM('AUTO 2024'!AC4:AC6) -> 2044.06 | I6: =H6*'AUTO 2024'!AA4 -> 1022.03 | L6: ='AUTO 2025'!AC13 -> 2159.0968 | M6: ='AUTO 2025'!AD13 -> 1338.64 | P6: ='AUTO 2026'!AC14 -> 2375.6379 | Q6: ='AUTO 2026'!AD14 -> 1377.87
A7: 1 | B7: C85 | C7: I85 | D7: =SUM('[1]AUTO 2024'!V7:V8) -> 164.23 | E7: =SUM('[1]AUTO 2024'!W7:W8) -> 0 | F7: ='AUTO 2024'!Q7 -> 1738.76 | G7: ='AUTO 2024'!Q8 -> 1918.46 | H7: =SUM('AUTO 2024'!AC7:AC8) -> 1925.76 | I7: =SUM('AUTO 2024'!AD7:AD8) -> 962.88 | L7: ='AUTO 2025'!AC14 -> 2038.46 | M7: ='AUTO 2025'!AD14 -> 1019.23 | N7: ='[1]AUTO 2026'!V15 -> 0 | O7: ='[1]AUTO 2026'!W15 -> 0 | P7: ='AUTO 2026'!AC15 -> 2144.58 | Q7: ='AUTO 2026'!AD15 -> 1072.29
A8: 1 | B8: C84 | C8: I84 | F8: ='AUTO 2024'!Q9 -> 1711.25 | G8: ='AUTO 2024'!Q10 -> 2097.26 | H8: =SUM('AUTO 2024'!AC9:AC10) -> 2092.32 | I8: =SUM('AUTO 2024'!AD9:AD10) -> 1046.16 | L8: ='AUTO 2025'!AC15 -> 2215.26 | M8: ='AUTO 2025'!AD15 -> 1107.63
A9: 1 | B9: C83 | C9: I83 | D9: =SUM('[1]AUTO 2024'!V11:V12) -> 613.25 | E9: =SUM('[1]AUTO 2024'!W11:W12) -> 0 | F9: ='AUTO 2024'!Q11 -> 1905.54 | G9: ='AUTO 2024'!Q12 -> 2122.14 | H9: =SUM('AUTO 2024'!AC11:AC12) -> 2118.04 | I9: =SUM('AUTO 2024'!AD11:AD12) -> 1059.02 | L9: ='AUTO 2025'!AC17 -> 2239.66 | M9: ='AUTO 2025'!AD17 -> 1119.83 | P9: ='AUTO 2026'!AC16 -> 2331.16 | Q9: ='AUTO 2026'!AD16 -> 1165.58
A10: 1 | B10: C81 | C10: I81 | F10: ='AUTO 2024'!Q15 -> 1906.38 | G10: ='AUTO 2024'!Q16 -> 2122.5 | H10: =SUM('AUTO 2024'!AC15:AC16) -> 2118.54 | I10: =SUM('AUTO 2024'!AD15:AD16) -> 1059.27 | L10: ='AUTO 2025'!AC19 -> 2240.04 | M10: ='AUTO 2025'!AD19 -> 1120.02 | P10: ='AUTO 2026'!AC18 -> 2331.9 | Q10: ='AUTO 2026'!AD18 -> 1165.95
A11: 1 | B11: C80 | C11: I80 | D11: =SUM('[1]AUTO 2024'!V17:V18) -> 1638.55 | E11: =SUM('[1]AUTO 2024'!W17:W18) -> 676 | F11: ='AUTO 2024'!Q17 -> 3662.08 | G11: ='AUTO 2024'!Q18 -> 4053.32 | H11: =SUM('AUTO 2024'!AC17:AC18) -> 4070.26 | I11: =SUM('AUTO 2024'!AD17:AD18) -> 2035.13 | L11: ='AUTO 2025'!AC20 -> 4577.28 | M11: ='AUTO 2025'!AD20 -> 2288.64 | P11: ='AUTO 2026'!AC19 -> 4770.76 | Q11: ='AUTO 2026'!AD19 -> 2385.38
A12: 1 | B12: C79 | C12: I79 | F12: ='AUTO 2024'!Q19 -> 2073.98 | G12: ='AUTO 2024'!Q20 -> 2286.6 | H12: =SUM('AUTO 2024'!AC19:AC20) -> 2291.3 | I12: =SUM('AUTO 2024'!AD19:AD20) -> 1145.65 | J12: ='[1]AUTO 2025'!V21 -> 2194 | K12: ='[1]AUTO 2025'!W21 -> 479 | L12: ='AUTO 2025'!AC21 -> 2413.26 | M12: ='AUTO 2025'!AD21 -> 1206.63 | P12: ='AUTO 2026'!AC20 -> 2510.92 | Q12: ='AUTO 2026'!AD20 -> 1255.46
A13: 1 | B13: C78 | C13: I78 | F13: ='AUTO 2024'!Q21 -> 1738.76 | G13: ='AUTO 2024'!Q22 -> 2004.82 | H13: =SUM('AUTO 2024'!AC21:AC22) -> 2009.28 | I13: =SUM('AUTO 2024'!AD21:AD22) -> 1004.64 | L13: ='AUTO 2025'!AC22 -> 2117.12 | M13: ='AUTO 2025'!AD22 -> 1058.56 | P13: ='AUTO 2026'!AC21 -> 2214.76 | Q13: ='AUTO 2026'!AD21 -> 1107.38
A14: 1 | B14: C70 | C14: I70 | F14: ='AUTO 2024'!Q33 -> 1762.54 | G14: ='AUTO 2024'!Q34 -> 2102.72 | H14: =SUM('AUTO 2024'!AC33:AC34) -> 2106.78 | I14: =SUM('AUTO 2024'!AD33:AD34) -> 1053.39 | L14: ='AUTO 2025'!AC28 -> 2218.94 | M14: ='AUTO 2025'!AD28 -> 1109.47 | P14: ='AUTO 2026'!AC28 -> 2318.52 | Q14: ='AUTO 2026'!AD28 -> 1159.26
A15: 1 | B15: C65 | C15: I65 | F15: ='AUTO 2024'!Q37 -> 1762.54 | G15: ='AUTO 2024'!Q38 -> 2188.38 | H15: =SUM('AUTO 2024'!AC37:AC38) -> 2193.44 | I15: =SUM('AUTO 2024'!AD37:AD38) -> 1096.72 | L15: ='AUTO 2025'!AC32 -> 2309.84 | M15: ='AUTO 2025'!AD32 -> 1154.92 | P15: ='AUTO 2026'!AC33 -> 2407.44 | Q15: ='AUTO 2026'!AD33 -> 1203.72
A16: 1 | B16: C63 | C16: I63 | D16: =SUM('[1]AUTO 2024'!V41:V42) -> 1486.36 | E16: =SUM('[1]AUTO 2024'!W41:W42) -> 908 | F16: ='AUTO 2024'!Q41 -> 1753.32 | G16: ='AUTO 2024'!Q42 -> 2142.54 | H16: =SUM('AUTO 2024'!AC41:AC42) -> 2147.34 | I16: =SUM('AUTO 2024'!AD41:AD42) -> 1073.67 | J16: =SUM('[1]AUTO 2025'!V35:V36) -> 691 | K16: =SUM('[1]AUTO 2025'!W35:W36) -> 479 | L16: ='AUTO 2025'!AC35 -> 2555.1 | M16: ='AUTO 2025'!AD35 -> 1277.55 | P16: ='AUTO 2026'!AC34 -> 2946.3871 | Q16: ='AUTO 2026'!AD34 -> 1826.76
A17: =SUM(A3:A16) -> 14 | D17: =SUM(D5:D16) -> 8629.46 | E17: =SUM(E5:E16) -> 2208 | F17: =SUM(F5:F16) -> 20015.15 | G17: =SUM(G5:G16) -> 23038.74 | H17: =SUM(H5:H16) -> 27273.02 | I17: =SUM(I5:I16) -> 13636.51 | J17: =SUM(J3:J16) -> 7681.16 | K17: =SUM(K3:K16) -> 2274 | L17: =SUM(L3:L16) -> 33040.657 | M17: =SUM(M3:M16) -> 16779.42 | N17: =SUM(N3:N16) -> 0 | O17: =SUM(O3:O16) -> 0 | P17: =SUM(P3:P16) -> 32771.105 | Q17: =SUM(Q3:Q16) -> 16929.17
A19: BUDGET | B19: ENTREE VEHICULES | H19: =SUM(H5:H6) -> 4199.96 | I19: =SUM(I5:I6) -> 2099.98 | L19: =SUM(L3:L4) -> 3681.76 | M19: =SUM(M3:M4) -> 1840.88 | P19: 0 | Q19: 0
B20: SORTIES VEHICULES | H20: 0 | I20: 0 | L20: =L8 -> 2215.26 | M20: =M8 -> 1107.63 | P20: 0 | Q20: 0
B22: PRIME MOYENNE VH.REF (N) | H22: =AVERAGE(H7:H16) -> 2307.306 | I22: =AVERAGE(I7:I16) -> 1153.653 | L22: =AVERAGE(L5:L16) -> 2446.5747 | M22: =AVERAGE(M5:M16) -> 1244.8783 | P22: =AVERAGE(P3:P7,P9:P16) -> 2520.8542 | Q22: =AVERAGE(Q3:Q7,Q9:Q16) -> 1302.2438
B23: PRIME MOYENNE VH.REF (N+1) | F23: =AVERAGE(F7:F16) -> 2001.515 | H23: =AVERAGE(H5:H16) -> 2272.7517 | I23: =AVERAGE(I5:I16) -> 1136.3758 | L23: =AVERAGE(L3:L7,L9:L16) -> 2371.1844 | M23: =AVERAGE(M3:M7,M9:M16) -> 1205.5223 | P23: =AVERAGE(P3:P7,P9:P16) -> 2520.8542 | Q23: =AVERAGE(Q3:Q7,Q9:Q16) -> 1302.2438
B24: PRIME MOYENNE ENSEMBLE | F24: =F17/F53 -> 2001.515 | H24: =H17/H53 -> 2272.7517 | I24: =I17/H53 -> 1136.3758 | L24: =L17/L53 -> 2360.0469 | M24: =M17/L53 -> 1198.53 | P24: =P17/P53 -> 2520.8542 | Q24: =Q17/P53 -> 1302.2438
B26: H.MOYENNE CONSTANTE | H26: =(H22-F23)/F23*100 -> 15.277977 | L26: =(L22-H23)/H23*100 -> 7.6481327 | M26: =(M22-I23)/I23*100 -> 9.5481175 | P26: =(P22-L23)/L23*100 -> 6.3120299 | Q26: =(Q22-M23)/M23*100 -> 8.023206
B27: H.MOYENNE GENERALE | H27: =(H24-F24)/F24*100 -> 13.551568 | L27: =(L24-H24)/H24*100 -> 3.8409496 | M27: =(M24-I24)/I24*100 -> 5.469508 | P27: =(P24-L24)/L24*100 -> 6.8137341 | Q27: =(Q24-M24)/M24*100 -> 8.653421
B29: ACC. RESPONSABLE | D29: 2024 | J29: 2025 | N29: 2026
B30: Conducteur | C30: Immatriculation | D30: Nombre sinistres | E30: Type | F30: - | G30: Variation primes N (%) | H30: - | I30: - | J30: Nombre sinistres | K30: Type | L30: Variation hors B/M (%) | M30: Varations B/M (%) | N30: Nombre sinistres | O30: Type | P30: Variation hors B/M (%) | Q30: Varations B/M (%)
A31: 1 | B31: C96 | C31: 96 | J31: 1 | K31: BDG | P31: =(P3-L3)/L3*100 -> 5.2362975 | Q31: =(Q3-M3)/M3*100 -> 5.2362975
A32: 1 | B32: C89 | C32: I89 | J32: 1 | K32: ACC | P32: =(P4-L4)/L4*100 -> 12.393398 | Q32: =(Q4-M4)/M4*100 -> 12.393398
A33: 1 | B33: C87 | C33: I87 | J33: 1 | K33: COLL ? | L33: =(L5-H5)/H5*100 -> 5.5169535 | M33: =(M5-I5)/I5*100 -> 5.5169535 | P33: =(P5-L5)/L5*100 -> 4.7704454 | Q33: =(Q5-M5)/M5*100 -> 4.7704454
A34: 1 | B34: C86 | C34: I86 | D34: 1 | E34: COLL | L34: =(L6-H6)/H6*100 -> 5.627857 | M34: =(M6-I6)/I6*100 -> 30.978543 | P34: =(P6-L6)/L6*100 -> 10.029247 | Q34: =(Q6-M6)/M6*100 -> 2.9305863
A35: 1 | B35: C85 | C35: I85 | D35: 1 | E35: BDG | G35: =(G7-F7)/F7*100 -> 10.334951 | L35: =(L7-H7)/H7*100 -> 5.852235 | M35: =(M7-I7)/I7*100 -> 5.852235 | N35: 1 | O35: BDG | P35: =(P7-L7)/L7*100 -> 5.2058907 | Q35: =(Q7-M7)/M7*100 -> 5.2058907
A36: 1 | B36: C84 | C36: I84 | G36: =(G8-F8)/F8*100 -> 22.557195 | L36: =(L8-H8)/H8*100 -> 5.8757743 | M36: =(M8-I8)/I8*100 -> 5.8757743
A37: 1 | B37: C83 | C37: I83 | D37: 1 | E37: BDG | G37: =(G9-F9)/F9*100 -> 11.366857 | L37: =(L9-H9)/H9*100 -> 5.7421012 | M37: =(M9-I9)/I9*100 -> 5.7421012 | P37: =(P9-L9)/L9*100 -> 4.0854415 | Q37: =(Q9-M9)/M9*100 -> 4.0854415
A38: 1 | B38: C81 | C38: I81 | G38: =(G10-F10)/F10*100 -> 11.336669 | L38: =(L10-H10)/H10*100 -> 5.7350817 | M38: =(M10-I10)/I10*100 -> 5.7350817 | P38: =(P10-L10)/L10*100 -> 4.1008196 | Q38: =(Q10-M10)/M10*100 -> 4.1008196
A39: 1 | B39: C80 | C39: I80 | D39: 2 | E39: ACC / BDG | G39: =(G11-F11)/F11*100 -> 10.683546 | L39: =(L11-H11)/H11*100 -> 12.456698 | M39: =(M11-I11)/I11*100 -> 12.456698 | P39: =(P11-L11)/L11*100 -> 4.2269645 | Q39: =(Q11-M11)/M11*100 -> 4.2269645
A40: 1 | B40: C79 | C40: I79 | G40: =(G12-F12)/F12*100 -> 10.251786 | J40: 1 | K40: CLIM | L40: =(L12-H12)/H12*100 -> 5.3227425 | M40: =(M12-I12)/I12*100 -> 5.3227425 | P40: =(P12-L12)/L12*100 -> 4.0468081 | Q40: =(Q12-M12)/M12*100 -> 4.0468081
A41: 1 | B41: C78 | C41: I78 | G41: =(G13-F13)/F13*100 -> 15.301709 | L41: =(L13-H13)/H13*100 -> 5.3670967 | M41: =(M13-I13)/I13*100 -> 5.3670967 | P41: =(P13-L13)/L13*100 -> 4.6119256 | Q41: =(Q13-M13)/M13*100 -> 4.6119256
A42: 1 | B42: C70 | C42: I70 | G42: =(G14-F14)/F14*100 -> 19.300555 | L42: =(L14-H14)/H14*100 -> 5.3237642 | M42: =(M14-I14)/I14*100 -> 5.3237642 | P42: =(P14-L14)/L14*100 -> 4.4877284 | Q42: =(Q14-M14)/M14*100 -> 4.4877284
A43: 1 | B43: C65 | C43: I65 | G43: =(G15-F15)/F15*100 -> 24.160586 | L43: =(L15-H15)/H15*100 -> 5.3067328 | M43: =(M15-I15)/I15*100 -> 5.3067328 | P43: =(P15-L15)/L15*100 -> 4.2254009 | Q43: =(Q15-M15)/M15*100 -> 4.2254009
A44: 1 | B44: C63 | C44: I63 | D44: 2 | E44: ACC | G44: =(G16-F16)/F16*100 -> 22.199028 | J44: 2 | K44: ACC/BDG | L44: =(L16-H16)/H16*100 -> 18.989075 | M44: =(M16-I16)/I16*100 -> 18.989075 | P44: =(P16-L16)/L16*100 -> 15.313964 | Q44: =(Q16-M16)/M16*100 -> 42.989315
...

Sheet VH SERVICE
C1: 2024 | I1: 2025 | M1: 2026
B2: Immatriculation | C2: Coût | D2: Franchise | E2: Primes annuelles N-X | F2: Primes annuelles N | G2: Primes hors B/M | H2: Primes avec B/M | I2: Coût | J2: Franchise | K2: Primes hors B/M | L2: Primes avec B/M | M2: Coût | N2: Franchise | O2: Primes hors B/M | P2: Primes avec B/M
A3: 1 | B3: I97 | O3: ='AUTO 2026'!AC3 -> 2000.46 | P3: ='AUTO 2026'!AD3 -> 1000.23
A4: 1 | B4: I95 | K4: ='AUTO 2025'!Q4 -> 1793.24 | L4: =K4*'AUTO 2025'!AA4 -> 896.62 | O4: ='AUTO 2026'!AC5 -> 1874.94 | P4: ='AUTO 2026'!AD5 -> 937.47
A5: 1 | B5: I94 | K5: ='AUTO 2025'!Q5 -> 1793.24 | L5: =K5*'AUTO 2025'!AA5 -> 896.62 | O5: ='AUTO 2026'!AC6 -> 1874.94 | P5: ='AUTO 2026'!AD6 -> 937.47
A6: 1 | B6: I93 | I6: ='[1]AUTO 2025'!V6 -> 235 | J6: ='[1]AUTO 2025'!W6 -> 0 | K6: ='AUTO 2025'!Q6 -> 1793.24 | L6: =K6*'AUTO 2025'!AA6 -> 896.62 | O6: ='AUTO 2026'!AC7 -> 1874.94 | P6: ='AUTO 2026'!AD7 -> 937.47
A7: 1 | B7: I92 | I7: ='[1]AUTO 2025'!V7 -> 282 | J7: ='[1]AUTO 2025'!W7 -> 0 | K7: ='AUTO 2025'!Q7 -> 1793.24 | L7: =K7*'AUTO 2025'!AA7 -> 896.62 | O7: ='AUTO 2026'!AC8 -> 1874.94 | P7: ='AUTO 2026'!AD8 -> 937.47
A8: 1 | B8: I91 | K8: ='AUTO 2025'!Q8 -> 1881.34 | L8: =K8*'AUTO 2025'!AA8 -> 940.67 | O8: ='AUTO 2026'!AC9 -> 1977.82 | P8: ='AUTO 2026'!AD9 -> 988.91
A9: 1 | B9: I90 | K9: ='AUTO 2025'!Q9 -> 1881.34 | L9: =K9*'AUTO 2025'!AA9 -> 940.67 | O9: ='AUTO 2026'!AC10 -> 1977.82 | P9: ='AUTO 2026'!AD10 -> 988.91
A10: 1 | B10: I88 | K10: ='AUTO 2025'!Q11 -> 1842.2 | L10: =K10*'AUTO 2025'!AA11 -> 921.1 | O10: ='AUTO 2026'!AC12 -> 1927.78 | P10: ='AUTO 2026'!AD12 -> 963.89
A11: 1 | B11: I82 | C11: =SUM('[1]AUTO 2024'!V13:V14) -> 1500.79 | D11: =SUM('[1]AUTO 2024'!W13:W14) -> 454 | E11: ='AUTO 2024'!Q13 -> 1906.38 | F11: ='AUTO 2024'!Q14 -> 2122.5 | G11: =SUM('AUTO 2024'!AC13:AC14) -> 2118.54 | H11: =SUM('AUTO 2024'!AD13:AD14) -> 1059.27 | K11: ='AUTO 2025'!AC18 -> 2336.98 | L11: ='AUTO 2025'!AD18 -> 1168.49 | O11: ='AUTO 2026'!AC17 -> 2432.28 | P11: ='AUTO 2026'!AD17 -> 1216.14
A12: 1 | B12: I77 | C12: =SUM('[1]AUTO 2024'!V23) -> 1422.25 | D12: =SUM('[1]AUTO 2024'!W23) -> 454 | E12: ='AUTO 2024'!Q23 -> 1767.82 | G12: =SUM('AUTO 2024'!AC23) -> 2177.48 | H12: =SUM('AUTO 2024'!AD23) -> 1088.74 | I12: ='[1]AUTO 2025'!V23 -> 219 | J12: ='[1]AUTO 2025'!W23 -> 0 | K12: ='AUTO 2025'!AC23 -> 2543.34 | L12: ='AUTO 2025'!AD23 -> 1271.67 | O12: ='AUTO 2026'!AC22 -> 2672.02 | P12: ='AUTO 2026'!AD22 -> 1336.01
A13: 1 | B13: I75 | C13: =SUM('[1]AUTO 2024'!V25:V26) -> 303.67 | D13: =SUM('[1]AUTO 2024'!W25:W26) -> 0 | E13: ='AUTO 2024'!Q25 -> 1594.08 | F13: ='AUTO 2024'!Q26 -> 1973.72 | G13: =SUM('AUTO 2024'!AC25:AC26) -> 1977.94 | H13: =SUM('AUTO 2024'!AD25:AD26) -> 988.97 | K13: ='AUTO 2025'!AC24 -> 2083.2 | L13: ='AUTO 2025'!AD24 -> 1041.6 | O13: ='AUTO 2026'!AC24 -> 2170.26 | P13: ='AUTO 2026'!AD24 -> 1085.13
A14: 1 | B14: I74 | C14: =SUM('[1]AUTO 2024'!V27:V28) -> 244.2 | D14: =SUM('[1]AUTO 2024'!W27:W28) -> 0 | E14: ='AUTO 2024'!Q27 -> 1594.08 | F14: ='AUTO 2024'!Q28 -> 1973.72 | G14: =SUM('AUTO 2024'!AC27:AC28) -> 1977.94 | H14: =SUM('AUTO 2024'!AD27:AD28) -> 988.97 | K14: ='AUTO 2025'!AC25 -> 2082.9 | L14: ='AUTO 2025'!AD25 -> 1041.45 | O14: ='AUTO 2026'!AC25 -> 2190.82 | P14: ='AUTO 2026'!AD25 -> 1095.41
A15: 1 | B15: I72 | E15: ='AUTO 2024'!Q29 -> 1577.6 | F15: ='AUTO 2024'!Q30 -> 1974.4 | G15: =SUM('AUTO 2024'!AC29:AC30) -> 1970.86 | H15: =SUM('AUTO 2024'!AD29:AD30) -> 985.43 | K15: ='AUTO 2025'!AC26 -> 2083.62 | L15: ='AUTO 2025'!AD26 -> 1041.81 | O15: ='AUTO 2026'!AC26 -> 2177.46 | P15: ='AUTO 2026'!AD26 -> 1088.73
A16: 1 | B16: I71 | C16: =SUM('[1]AUTO 2024'!V31:V32) -> 6038.97 | D16: =SUM('[1]AUTO 2024'!W31:W32) -> 268 | E16: ='AUTO 2024'!Q31 -> 1543.92 | F16: ='AUTO 2024'!Q32 -> 1932.48 | G16: =SUM('AUTO 2024'!AC31:AC32) -> 1928.96 | H16: =SUM('AUTO 2024'!AD31:AD32) -> 964.48 | I16: ='[1]AUTO 2025'!V27 -> 0 | J16: ='[1]AUTO 2025'!W27 -> 283 | K16: ='AUTO 2025'!AC27 -> 2313.14 | L16: ='AUTO 2025'!AD27 -> 1156.57 | O16: ='AUTO 2026'!AC27 -> 2419.74 | P16: ='AUTO 2026'!AD27 -> 1209.87
A17: 1 | B17: I69 | E17: ='AUTO 2024'!Q35 -> 1591.8 | G17: ='AUTO 2024'!AC35 -> 1983.9 | H17: =SUM('AUTO 2024'!AD35) -> 991.95 | I17: =SUM('[1]AUTO 2025'!V29:V30) -> 1475 | J17: =SUM('[1]AUTO 2025'!W29:W30) -> 283 | K17: ='AUTO 2025'!AC29 -> 2094.04 | L17: ='AUTO 2025'!AD29 -> 1047.02 | O17: ='AUTO 2026'!AC29 -> 2183.9 | P17: ='AUTO 2026'!AD29 -> 1091.95
A18: 1 | B18: I68 | E18: ='AUTO 2024'!Q36 -> 1591.8 | G18: ='AUTO 2024'!AC36 -> 1983.94 | H18: =SUM('AUTO 2024'!AD36) -> 991.97 | K18: ='AUTO 2025'!AC31 -> 2093.72 | L18: ='AUTO 2025'!AD31 -> 1046.86 | O18: ='AUTO 2026'!AC31 -> 2183.28 | P18: ='AUTO 2026'!AD31 -> 1091.64
A19: 1 | B19: I64 | E19: ='AUTO 2024'!Q39 -> 1762.54 | F19: ='AUTO 2024'!Q40 -> 2188.38 | G19: =SUM('AUTO 2024'!AC39:AC40) -> 2193.44 | H19: =SUM('AUTO 2024'!AD39:AD40) -> 1096.72 | K19: ='AUTO 2025'!AC33 -> 2309.84 | L19: ='AUTO 2025'!AD33 -> 1154.92
